Workbook
Name List_Equip: 'Hidden_Data'!$A$1:$A$27
Name List_PF: 'Hidden_Data'!$B$1:$B$4
Name List_YN: 'Hidden_Data'!$C$1:$C$2
Name List_Crit: 'Hidden_Data'!$D$1:$D$5
Name List_Maint: 'Hidden_Data'!$E$1:$E$3
Name List_NEC: 'Hidden_Data'!$M$1:$M$166
Name List_Phase: 'Hidden_Data'!$H$1:$H$3
Name List_Wire: 'Hidden_Data'!$I$1:$I$3
Name List_Comp: 'Hidden_Data'!$J$1:$J$9
Name List_US_Mode: 'Hidden_Data'!$K$1:$K$6
Name List_IR_Phase: 'Hidden_Data'!$L$1:$L$6

Sheet Equipment Information
A1: Asset Tag | B1: Functional Name | C1: Location | D1: Equipment Type | E1: Manufacturer | F1: Model | G1: Serial # | H1: Voltage | I1: Criticality | J1: Maint. Status | K1: Health Score | L1: Program Status | M1: Notes
K2: =IF(A2="","", IF(OR(SUMIF('Code Violations'!A:A, A2, 'Code Violations'!T:T)>=5, VLOOKUP(A2, 'Master Dashboard'!A:L, 9, FALSE)="FAIL", VLOOKUP(A2, 'Master Dashboard'!A:L, 10, FALSE)="FAIL", ISNUMBER(SEARCH("Critical", J2))), "3-Red", IF(SUMIF('Code Violations'!A:A, A2, 'Code Violations'!T:T)>=1, "2-Yellow", "1-White"))) | L2: =IF(J2="","", IF(ISNUMBER(SEARCH("Critical", J2)), "CRITICAL FAIL", IF(ISNUMBER(SEARCH("Overdue", J2)), "FAIL", "COMPLIANT")))
K3: =IF(A3="","", IF(OR(SUMIF('Code Violations'!A:A, A3, 'Code Violations'!T:T)>=5, VLOOKUP(A3, 'Master Dashboard'!A:L, 9, FALSE)="FAIL", VLOOKUP(A3, 'Master Dashboard'!A:L, 10, FALSE)="FAIL", ISNUMBER(SEARCH("Critical", J3))), "3-Red", IF(SUMIF('Code Violations'!A:A, A3, 'Code Violations'!T:T)>=1, "2-Yellow", "1-White"))) | L3: =IF(J3="","", IF(ISNUMBER(SEARCH("Critical", J3)), "CRITICAL FAIL", IF(ISNUMBER(SEARCH("Overdue", J3)), "FAIL", "COMPLIANT")))
K4: =IF(A4="","", IF(OR(SUMIF('Code Violations'!A:A, A4, 'Code Violations'!T:T)>=5, VLOOKUP(A4, 'Master Dashboard'!A:L, 9, FALSE)="FAIL", VLOOKUP(A4, 'Master Dashboard'!A:L, 10, FALSE)="FAIL", ISNUMBER(SEARCH("Critical", J4))), "3-Red", IF(SUMIF('Code Violations'!A:A, A4, 'Code Violations'!T:T)>=1, "2-Yellow", "1-White"))) | L4: =IF(J4="","", IF(ISNUMBER(SEARCH("Critical", J4)), "CRITICAL FAIL", IF(ISNUMBER(SEARCH("Overdue", J4)), "FAIL", "COMPLIANT")))
K5: =IF(A5="","", IF(OR(SUMIF('Code Violations'!A:A, A5, 'Code Violations'!T:T)>=5, VLOOKUP(A5, 'Master Dashboard'!A:L, 9, FALSE)="FAIL", VLOOKUP(A5, 'Master Dashboard'!A:L, 10, FALSE)="FAIL", ISNUMBER(SEARCH("Critical", J5))), "3-Red", IF(SUMIF('Code Violations'!A:A, A5, 'Code Violations'!T:T)>=1, "2-Yellow", "1-White"))) | L5: =IF(J5="","", IF(ISNUMBER(SEARCH("Critical", J5)), "CRITICAL FAIL", IF(ISNUMBER(SEARCH("Overdue", J5)), "FAIL", "COMPLIANT")))
K6: =IF(A6="","", IF(OR(SUMIF('Code Violations'!A:A, A6, 'Code Violations'!T:T)>=5, VLOOKUP(A6, 'Master Dashboard'!A:L, 9, FALSE)="FAIL", VLOOKUP(A6, 'Master Dashboard'!A:L, 10, FALSE)="FAIL", ISNUMBER(SEARCH("Critical", J6))), "3-Red", IF(SUMIF('Code Violations'!A:A, A6, 'Code Violations'!T:T)>=1, "2-Yellow", "1-White"))) | L6: =IF(J6="","", IF(ISNUMBER(SEARCH("Critical", J6)), "CRITICAL FAIL", IF(ISNUMBER(SEARCH("Overdue", J6)), "FAIL", "COMPLIANT")))
K7: =IF(A7="","", IF(OR(SUMIF('Code Violations'!A:A, A7, 'Code Violations'!T:T)>=5, VLOOKUP(A7, 'Master Dashboard'!A:L, 9, FALSE)="FAIL", VLOOKUP(A7, 'Master Dashboard'!A:L, 10, FALSE)="FAIL", ISNUMBER(SEARCH("Critical", J7))), "3-Red", IF(SUMIF('Code Violations'!A:A, A7, 'Code Violations'!T:T)>=1, "2-Yellow", "1-White"))) | L7: =IF(J7="","", IF(ISNUMBER(SEARCH("Critical", J7)), "CRITICAL FAIL", IF(ISNUMBER(SEARCH("Overdue", J7)), "FAIL", "COMPLIANT")))
K8: =IF(A8="","", IF(OR(SUMIF('Code Violations'!A:A, A8, 'Code Violations'!T:T)>=5, VLOOKUP(A8, 'Master Dashboard'!A:L, 9, FALSE)="FAIL", VLOOKUP(A8, 'Master Dashboard'!A:L, 10, FALSE)="FAIL", ISNUMBER(SEARCH("Critical", J8))), "3-Red", IF(SUMIF('Code Violations'!A:A, A8, 'Code Violations'!T:T)>=1, "2-Yellow", "1-White"))) | L8: =IF(J8="","", IF(ISNUMBER(SEARCH("Critical", J8)), "CRITICAL FAIL", IF(ISNUMBER(SEARCH("Overdue", J8)), "FAIL", "COMPLIANT")))
K9: =IF(A9="","", IF(OR(SUMIF('Code Violations'!A:A, A9, 'Code Violations'!T:T)>=5, VLOOKUP(A9, 'Master Dashboard'!A:L, 9, FALSE)="FAIL", VLOOKUP(A9, 'Master Dashboard'!A:L, 10, FALSE)="FAIL", ISNUMBER(SEARCH("Critical", J9))), "3-Red", IF(SUMIF('Code Violations'!A:A, A9, 'Code Violations'!T:T)>=1, "2-Yellow", "1-White"))) | L9: =IF(J9="","", IF(ISNUMBER(SEARCH("Critical", J9)), "CRITICAL FAIL", IF(ISNUMBER(SEARCH("Overdue", J9)), "FAIL", "COMPLIANT")))
K10: =IF(A10="","", IF(OR(SUMIF('Code Violations'!A:A, A10, 'Code Violations'!T:T)>=5, VLOOKUP(A10, 'Master Dashboard'!A:L, 9, FALSE)="FAIL", VLOOKUP(A10, 'Master Dashboard'!A:L, 10, FALSE)="FAIL", ISNUMBER(SEARCH("Critical", J10))), "3-Red", IF(SUMIF('Code Violations'!A:A, A10, 'Code Violations'!T:T)>=1, "2-Yellow", "1-White"))) | L10: =IF(J10="","", IF(ISNUMBER(SEARCH("Critical", J10)), "CRITICAL FAIL", IF(ISNUMBER(SEARCH("Overdue", J10)), "FAIL", "COMPLIANT")))
K11: =IF(A11="","", IF(OR(SUMIF('Code Violations'!A:A, A11, 'Code Violations'!T:T)>=5, VLOOKUP(A11, 'Master Dashboard'!A:L, 9, FALSE)="FAIL", VLOOKUP(A11, 'Master Dashboard'!A:L, 10, FALSE)="FAIL", ISNUMBER(SEARCH("Critical", J11))), "3-Red", IF(SUMIF('Code Violations'!A:A, A11, 'Code Violations'!T:T)>=1, "2-Yellow", "1-White"))) | L11: =IF(J11="","", IF(ISNUMBER(SEARCH("Critical", J11)), "CRITICAL FAIL", IF(ISNUMBER(SEARCH("Overdue", J11)), "FAIL", "COMPLIANT")))
K12: =IF(A12="","", IF(OR(SUMIF('Code Violations'!A:A, A12, 'Code Violations'!T:T)>=5, VLOOKUP(A12, 'Master Dashboard'!A:L, 9, FALSE)="FAIL", VLOOKUP(A12, 'Master Dashboard'!A:L, 10, FALSE)="FAIL", ISNUMBER(SEARCH("Critical", J12))), "3-Red", IF(SUMIF('Code Violations'!A:A, A12, 'Code Violations'!T:T)>=1, "2-Yellow", "1-White"))) | L12: =IF(J12="","", IF(ISNUMBER(SEARCH("Critical", J12)), "CRITICAL FAIL", IF(ISNUMBER(SEARCH("Overdue", J12)), "FAIL", "COMPLIANT")))
K13: =IF(A13="","", IF(OR(SUMIF('Code Violations'!A:A, A13, 'Code Violations'!T:T)>=5, VLOOKUP(A13, 'Master Dashboard'!A:L, 9, FALSE)="FAIL", VLOOKUP(A13, 'Master Dashboard'!A:L, 10, FALSE)="FAIL", ISNUMBER(SEARCH("Critical", J13))), "3-Red", IF(SUMIF('Code Violations'!A:A, A13, 'Code Violations'!T:T)>=1, "2-Yellow", "1-White"))) | L13: =IF(J13="","", IF(ISNUMBER(SEARCH("Critical", J13)), "CRITICAL FAIL", IF(ISNUMBER(SEARCH("Overdue", J13)), "FAIL", "COMPLIANT")))
... K499: =IF(A499="","", IF(OR(SUMIF('Code Violations'!A:A, A499, 'Code Violations'!T:T)>=5, VLOOKUP(A499, 'Master Dashboard'!A:L, 9, FALSE)="FAIL", VLOOKUP(A499, 'Master Dashboard'!A:L, 10, FALSE)="FAIL", ISNUMBER(SEARCH("Critical", J499))), "3-Red", IF(SUMIF('Code Violations'!A:A, A499, 'Code Violations'!T:T)>=1, "2-Yellow", "1-White"))) | L499: =IF(J499="","", IF(ISNUMBER(SEARCH("Critical", J499)), "CRITICAL FAIL", IF(ISNUMBER(SEARCH("Overdue", J499)), "FAIL", "COMPLIANT")))

Sheet Master Dashboard
A1: Asset Tag | B1: Functional Name | C1: Location | D1: Equipment Type | E1: Energized | F1: Insul | G1: DLRO | H1: Torque | I1: IR | J1: US | K1: Code | L1: OVERALL STATUS
A2: =IF('Equipment Information'!A2="","", 'Equipment Information'!A2) | B2: =IF('Equipment Information'!B2="","", 'Equipment Information'!B2) | C2: =IF('Equipment Information'!C2="","", 'Equipment Information'!C2) | D2: =IF('Equipment Information'!D2="","", 'Equipment Information'!D2) | E2: =IF(A2="","", IFERROR(VLOOKUP(A2, 'Energized Data'!A:T, 20, FALSE), "N/A")) | F2: =IF(A2="","", IFERROR(VLOOKUP(A2, 'Insulation'!A:J, 9, FALSE), "N/A")) | G2: =IF(A2="","", IFERROR(VLOOKUP(A2, 'DLRO'!A:I, 8, FALSE), "N/A")) | H2: =IF(A2="","", IFERROR(VLOOKUP(A2, 'Torque'!A:I, 8, FALSE), "N/A")) | I2: =IF(A2="","", IFERROR(VLOOKUP(A2, 'Infrared'!A:G, 6, FALSE), "N/A")) | J2: =IF(A2="","", IFERROR(VLOOKUP(A2, 'Ultrasonic'!A:H, 7, FALSE), "N/A")) | K2: =IF(A2="","", IFERROR(VLOOKUP(A2, 'Code Violations'!A:V, 22, FALSE), "N/A")) | L2: =IF(A2="","", IF(COUNTIF(E2:K2, "FAIL")>0, "FAIL", "PASS"))
A3: =IF('Equipment Information'!A3="","", 'Equipment Information'!A3) | B3: =IF('Equipment Information'!B3="","", 'Equipment Information'!B3) | C3: =IF('Equipment Information'!C3="","", 'Equipment Information'!C3) | D3: =IF('Equipment Information'!D3="","", 'Equipment Information'!D3) | E3: =IF(A3="","", IFERROR(VLOOKUP(A3, 'Energized Data'!A:T, 20, FALSE), "N/A")) | F3: =IF(A3="","", IFERROR(VLOOKUP(A3, 'Insulation'!A:J, 9, FALSE), "N/A")) | G3: =IF(A3="","", IFERROR(VLOOKUP(A3, 'DLRO'!A:I, 8, FALSE), "N/A")) | H3: =IF(A3="","", IFERROR(VLOOKUP(A3, 'Torque'!A:I, 8, FALSE), "N/A")) | I3: =IF(A3="","", IFERROR(VLOOKUP(A3, 'Infrared'!A:G, 6, FALSE), "N/A")) | J3: =IF(A3="","", IFERROR(VLOOKUP(A3, 'Ultrasonic'!A:H, 7, FALSE), "N/A")) | K3: =IF(A3="","", IFERROR(VLOOKUP(A3, 'Code Violations'!A:V, 22, FALSE), "N/A")) | L3: =IF(A3="","", IF(COUNTIF(E3:K3, "FAIL")>0, "FAIL", "PASS"))
A4: =IF('Equipment Information'!A4="","", 'Equipment Information'!A4) | B4: =IF('Equipment Information'!B4="","", 'Equipment Information'!B4) | C4: =IF('Equipment Information'!C4="","", 'Equipment Information'!C4) | D4: =IF('Equipment Information'!D4="","", 'Equipment Information'!D4) | E4: =IF(A4="","", IFERROR(VLOOKUP(A4, 'Energized Data'!A:T, 20, FALSE), "N/A")) | F4: =IF(A4="","", IFERROR(VLOOKUP(A4, 'Insulation'!A:J, 9, FALSE), "N/A")) | G4: =IF(A4="","", IFERROR(VLOOKUP(A4, 'DLRO'!A:I, 8, FALSE), "N/A")) | H4: =IF(A4="","", IFERROR(VLOOKUP(A4, 'Torque'!A:I, 8, FALSE), "N/A")) | I4: =IF(A4="","", IFERROR(VLOOKUP(A4, 'Infrared'!A:G, 6, FALSE), "N/A")) | J4: =IF(A4="","", IFERROR(VLOOKUP(A4, 'Ultrasonic'!A:H, 7, FALSE), "N/A")) | K4: =IF(A4="","", IFERROR(VLOOKUP(A4, 'Code Violations'!A:V, 22, FALSE), "N/A")) | L4: =IF(A4="","", IF(COUNTIF(E4:K4, "FAIL")>0, "FAIL", "PASS"))
A5: =IF('Equipment Information'!A5="","", 'Equipment Information'!A5) | B5: =IF('Equipment Information'!B5="","", 'Equipment Information'!B5) | C5: =IF('Equipment Information'!C5="","", 'Equipment Information'!C5) | D5: =IF('Equipment Information'!D5="","", 'Equipment Information'!D5) | E5: =IF(A5="","", IFERROR(VLOOKUP(A5, 'Energized Data'!A:T, 20, FALSE), "N/A")) | F5: =IF(A5="","", IFERROR(VLOOKUP(A5, 'Insulation'!A:J, 9, FALSE), "N/A")) | G5: =IF(A5="","", IFERROR(VLOOKUP(A5, 'DLRO'!A:I, 8, FALSE), "N/A")) | H5: =IF(A5="","", IFERROR(VLOOKUP(A5, 'Torque'!A:I, 8, FALSE), "N/A")) | I5: =IF(A5="","", IFERROR(VLOOKUP(A5, 'Infrared'!A:G, 6, FALSE), "N/A")) | J5: =IF(A5="","", IFERROR(VLOOKUP(A5, 'Ultrasonic'!A:H, 7, FALSE), "N/A")) | K5: =IF(A5="","", IFERROR(VLOOKUP(A5, 'Code Violations'!A:V, 22, FALSE), "N/A")) | L5: =IF(A5="","", IF(COUNTIF(E5:K5, "FAIL")>0, "FAIL", "PASS"))
A6: =IF('Equipment Information'!A6="","", 'Equipment Information'!A6) | B6: =IF('Equipment Information'!B6="","", 'Equipment Information'!B6) | C6: =IF('Equipment Information'!C6="","", 'Equipment Information'!C6) | D6: =IF('Equipment Information'!D6="","", 'Equipment Information'!D6) | E6: =IF(A6="","", IFERROR(VLOOKUP(A6, 'Energized Data'!A:T, 20, FALSE), "N/A")) | F6: =IF(A6="","", IFERROR(VLOOKUP(A6, 'Insulation'!A:J, 9, FALSE), "N/A")) | G6: =IF(A6="","", IFERROR(VLOOKUP(A6, 'DLRO'!A:I, 8, FALSE), "N/A")) | H6: =IF(A6="","", IFERROR(VLOOKUP(A6, 'Torque'!A:I, 8, FALSE), "N/A")) | I6: =IF(A6="","", IFERROR(VLOOKUP(A6, 'Infrared'!A:G, 6, FALSE), "N/A")) | J6: =IF(A6="","", IFERROR(VLOOKUP(A6, 'Ultrasonic'!A:H, 7, FALSE), "N/A")) | K6: =IF(A6="","", IFERROR(VLOOKUP(A6, 'Code Violations'!A:V, 22, FALSE), "N/A")) | L6: =IF(A6="","", IF(COUNTIF(E6:K6, "FAIL")>0, "FAIL", "PASS"))
A7: =IF('Equipment Information'!A7="","", 'Equipment Information'!A7) | B7: =IF('Equipment Information'!B7="","", 'Equipment Information'!B7) | C7: =IF('Equipment Information'!C7="","", 'Equipment Information'!C7) | D7: =IF('Equipment Information'!D7="","", 'Equipment Information'!D7) | E7: =IF(A7="","", IFERROR(VLOOKUP(A7, 'Energized Data'!A:T, 20, FALSE), "N/A")) | F7: =IF(A7="","", IFERROR(VLOOKUP(A7, 'Insulation'!A:J, 9, FALSE), "N/A")) | G7: =IF(A7="","", IFERROR(VLOOKUP(A7, 'DLRO'!A:I, 8, FALSE), "N/A")) | H7: =IF(A7="","", IFERROR(VLOOKUP(A7, 'Torque'!A:I, 8, FALSE), "N/A")) | I7: =IF(A7="","", IFERROR(VLOOKUP(A7, 'Infrared'!A:G, 6, FALSE), "N/A")) | J7: =IF(A7="","", IFERROR(VLOOKUP(A7, 'Ultrasonic'!A:H, 7, FALSE), "N/A")) | K7: =IF(A7="","", IFERROR(VLOOKUP(A7, 'Code Violations'!A:V, 22, FALSE), "N/A")) | L7: =IF(A7="","", IF(COUNTIF(E7:K7, "FAIL")>0, "FAIL", "PASS"))
A8: =IF('Equipment Information'!A8="","", 'Equipment Information'!A8) | B8: =IF('Equipment Information'!B8="","", 'Equipment Information'!B8) | C8: =IF('Equipment Information'!C8="","", 'Equipment Information'!C8) | D8: =IF('Equipment Information'!D8="","", 'Equipment Information'!D8) | E8: =IF(A8="","", IFERROR(VLOOKUP(A8, 'Energized Data'!A:T, 20, FALSE), "N/A")) | F8: =IF(A8="","", IFERROR(VLOOKUP(A8, 'Insulation'!A:J, 9, FALSE), "N/A")) | G8: =IF(A8="","", IFERROR(VLOOKUP(A8, 'DLRO'!A:I, 8, FALSE), "N/A")) | H8: =IF(A8="","", IFERROR(VLOOKUP(A8, 'Torque'!A:I, 8, FALSE), "N/A")) | I8: =IF(A8="","", IFERROR(VLOOKUP(A8, 'Infrared'!A:G, 6, FALSE), "N/A")) | J8: =IF(A8="","", IFERROR(VLOOKUP(A8, 'Ultrasonic'!A:H, 7, FALSE), "N/A")) | K8: =IF(A8="","", IFERROR(VLOOKUP(A8, 'Code Violations'!A:V, 22, FALSE), "N/A")) | L8: =IF(A8="","", IF(COUNTIF(E8:K8, "FAIL")>0, "FAIL", "PASS"))
A9: =IF('Equipment Information'!A9="","", 'Equipment Information'!A9) | B9: =IF('Equipment Information'!B9="","", 'Equipment Information'!B9) | C9: =IF('Equipment Information'!C9="","", 'Equipment Information'!C9) | D9: =IF('Equipment Information'!D9="","", 'Equipment Information'!D9) | E9: =IF(A9="","", IFERROR(VLOOKUP(A9, 'Energized Data'!A:T, 20, FALSE), "N/A")) | F9: =IF(A9="","", IFERROR(VLOOKUP(A9, 'Insulation'!A:J, 9, FALSE), "N/A")) | G9: =IF(A9="","", IFERROR(VLOOKUP(A9, 'DLRO'!A:I, 8, FALSE), "N/A")) | H9: =IF(A9="","", IFERROR(VLOOKUP(A9, 'Torque'!A:I, 8, FALSE), "N/A")) | I9: =IF(A9="","", IFERROR(VLOOKUP(A9, 'Infrared'!A:G, 6, FALSE), "N/A")) | J9: =IF(A9="","", IFERROR(VLOOKUP(A9, 'Ultrasonic'!A:H, 7, FALSE), "N/A")) | K9: =IF(A9="","", IFERROR(VLOOKUP(A9, 'Code Violations'!A:V, 22, FALSE), "N/A")) | L9: =IF(A9="","", IF(COUNTIF(E9:K9, "FAIL")>0, "FAIL", "PASS"))
A10: =IF('Equipment Information'!A10="","", 'Equipment Information'!A10) | B10: =IF('Equipment Information'!B10="","", 'Equipment Information'!B10) | C10: =IF('Equipment Information'!C10="","", 'Equipment Information'!C10) | D10: =IF('Equipment Information'!D10="","", 'Equipment Information'!D10) | E10: =IF(A10="","", IFERROR(VLOOKUP(A10, 'Energized Data'!A:T, 20, FALSE), "N/A")) | F10: =IF(A10="","", IFERROR(VLOOKUP(A10, 'Insulation'!A:J, 9, FALSE), "N/A")) | G10: =IF(A10="","", IFERROR(VLOOKUP(A10, 'DLRO'!A:I, 8, FALSE), "N/A")) | H10: =IF(A10="","", IFERROR(VLOOKUP(A10, 'Torque'!A:I, 8, FALSE), "N/A")) | I10: =IF(A10="","", IFERROR(VLOOKUP(A10, 'Infrared'!A:G, 6, FALSE), "N/A")) | J10: =IF(A10="","", IFERROR(VLOOKUP(A10, 'Ultrasonic'!A:H, 7, FALSE), "N/A")) | K10: =IF(A10="","", IFERROR(VLOOKUP(A10, 'Code Violations'!A:V, 22, FALSE), "N/A")) | L10: =IF(A10="","", IF(COUNTIF(E10:K10, "FAIL")>0, "FAIL", "PASS"))
A11: =IF('Equipment Information'!A11="","", 'Equipment Information'!A11) | B11: =IF('Equipment Information'!B11="","", 'Equipment Information'!B11) | C11: =IF('Equipment Information'!C11="","", 'Equipment Information'!C11) | D11: =IF('Equipment Information'!D11="","", 'Equipment Information'!D11) | E11: =IF(A11="","", IFERROR(VLOOKUP(A11, 'Energized Data'!A:T, 20, FALSE), "N/A")) | F11: =IF(A11="","", IFERROR(VLOOKUP(A11, 'Insulation'!A:J, 9, FALSE), "N/A")) | G11: =IF(A11="","", IFERROR(VLOOKUP(A11, 'DLRO'!A:I, 8, FALSE), "N/A")) | H11: =IF(A11="","", IFERROR(VLOOKUP(A11, 'Torque'!A:I, 8, FALSE), "N/A")) | I11: =IF(A11="","", IFERROR(VLOOKUP(A11, 'Infrared'!A:G, 6, FALSE), "N/A")) | J11: =IF(A11="","", IFERROR(VLOOKUP(A11, 'Ultrasonic'!A:H, 7, FALSE), "N/A")) | K11: =IF(A11="","", IFERROR(VLOOKUP(A11, 'Code Violations'!A:V, 22, FALSE), "N/A")) | L11: =IF(A11="","", IF(COUNTIF(E11:K11, "FAIL")>0, "FAIL", "PASS"))
A12: =IF('Equipment Information'!A12="","", 'Equipment Information'!A12) | B12: =IF('Equipment Information'!B12="","", 'Equipment Information'!B12) | C12: =IF('Equipment Information'!C12="","", 'Equipment Information'!C12) | D12: =IF('Equipment Information'!D12="","", 'Equipment Information'!D12) | E12: =IF(A12="","", IFERROR(VLOOKUP(A12, 'Energized Data'!A:T, 20, FALSE), "N/A")) | F12: =IF(A12="","", IFERROR(VLOOKUP(A12, 'Insulation'!A:J, 9, FALSE), "N/A")) | G12: =IF(A12="","", IFERROR(VLOOKUP(A12, 'DLRO'!A:I, 8, FALSE), "N/A")) | H12: =IF(A12="","", IFERROR(VLOOKUP(A12, 'Torque'!A:I, 8, FALSE), "N/A")) | I12: =IF(A12="","", IFERROR(VLOOKUP(A12, 'Infrared'!A:G, 6, FALSE), "N/A")) | J12: =IF(A12="","", IFERROR(VLOOKUP(A12, 'Ultrasonic'!A:H, 7, FALSE), "N/A")) | K12: =IF(A12="","", IFERROR(VLOOKUP(A12, 'Code Violations'!A:V, 22, FALSE), "N/A")) | L12: =IF(A12="","", IF(COUNTIF(E12:K12, "FAIL")>0, "FAIL", "PASS"))
A13: =IF('Equipment Information'!A13="","", 'Equipment Information'!A13) | B13: =IF('Equipment Information'!B13="","", 'Equipment Information'!B13) | C13: =IF('Equipment Information'!C13="","", 'Equipment Information'!C13) | D13: =IF('Equipment Information'!D13="","", 'Equipment Information'!D13) | E13: =IF(A13="","", IFERROR(VLOOKUP(A13, 'Energized Data'!A:T, 20, FALSE), "N/A")) | F13: =IF(A13="","", IFERROR(VLOOKUP(A13, 'Insulation'!A:J, 9, FALSE), "N/A")) | G13: =IF(A13="","", IFERROR(VLOOKUP(A13, 'DLRO'!A:I, 8, FALSE), "N/A")) | H13: =IF(A13="","", IFERROR(VLOOKUP(A13, 'Torque'!A:I, 8, FALSE), "N/A")) | I13: =IF(A13="","", IFERROR(VLOOKUP(A13, 'Infrared'!A:G, 6, FALSE), "N/A")) | J13: =IF(A13="","", IFERROR(VLOOKUP(A13, 'Ultrasonic'!A:H, 7, FALSE), "N/A")) | K13: =IF(A13="","", IFERROR(VLOOKUP(A13, 'Code Violations'!A:V, 22, FALSE), "N/A")) | L13: =IF(A13="","", IF(COUNTIF(E13:K13, "FAIL")>0, "FAIL", "PASS"))
... A499: =IF('Equipment Information'!A499="","", 'Equipment Information'!A499) | B499: =IF('Equipment Information'!B499="","", 'Equipment Information'!B499) | C499: =IF('Equipment Information'!C499="","", 'Equipment Information'!C499) | D499: =IF('Equipment Information'!D499="","", 'Equipment Information'!D499) | E499: =IF(A499="","", IFERROR(VLOOKUP(A499, 'Energized Data'!A:T, 20, FALSE), "N/A")) | F499: =IF(A499="","", IFERROR(VLOOKUP(A499, 'Insulation'!A:J, 9, FALSE), "N/A")) | G499: =IF(A499="","", IFERROR(VLOOKUP(A499, 'DLRO'!A:I, 8, FALSE), "N/A")) | H499: =IF(A499="","", IFERROR(VLOOKUP(A499, 'Torque'!A:I, 8, FALSE), "N/A")) | I499: =IF(A499="","", IFERROR(VLOOKUP(A499, 'Infrared'!A:G, 6, FALSE), "N/A")) | J499: =IF(A499="","", IFERROR(VLOOKUP(A499, 'Ultrasonic'!A:H, 7, FALSE), "N/A")) | K499: =IF(A499="","", IFERROR(VLOOKUP(A499, 'Code Violations'!A:V, 22, FALSE), "N/A")) | L499: =IF(A499="","", IF(COUNTIF(E499:K499, "FAIL")>0, "FAIL", "PASS"))

Sheet Code Violations
A1: Tag | B1: Name | C1: Loc | D1: Violation 1 | E1: Sev 1 | F1: Corr 1? | G1: Violation 2 | H1: Sev 2 | I1: Corr 2? | J1: Violation 3 | K1: Sev 3 | L1: Corr 3? | M1: Violation 4 | N1: Sev 4 | O1: Corr 4? | P1: Violation 5 | Q1: Sev 5 | R1: Corr 5? | S1: Notes | T1: Net Points | U1: Status | V1: Result
A2: =IF('Equipment Information'!A2="","", 'Equipment Information'!A2) | B2: =IF('Equipment Information'!B2="","", 'Equipment Information'!B2) | C2: =IF('Equipment Information'!C2="","", 'Equipment Information'!C2) | E2: =IF(D2="","", IFERROR(VLOOKUP(D2, 'Hidden_Data'!M:N, 2, FALSE), "0")) | H2: =IF(G2="","", IFERROR(VLOOKUP(G2, 'Hidden_Data'!M:N, 2, FALSE), "0")) | K2: =IF(J2="","", IFERROR(VLOOKUP(J2, 'Hidden_Data'!M:N, 2, FALSE), "0")) | N2: =IF(M2="","", IFERROR(VLOOKUP(M2, 'Hidden_Data'!M:N, 2, FALSE), "0")) | Q2: =IF(P2="","", IFERROR(VLOOKUP(P2, 'Hidden_Data'!M:N, 2, FALSE), "0")) | T2: =IF(A2="","", SUM(IF(F2="Yes", 0, IF(E2="", 0, IFERROR(VALUE(MID(E2, SEARCH("(",E2)+1, 1)),0))), IF(I2="Yes", 0, IF(H2="", 0, IFERROR(VALUE(MID(H2, SEARCH("(",H2)+1, 1)),0))), IF(L2="Yes", 0, IF(K2="", 0, IFERROR(VALUE(MID(K2, SEARCH("(",K2)+1, 1)),0))), IF(O2="Yes", 0, IF(N2="", 0, IFERROR(VALUE(MID(N2, SEARCH("(",N2)+1, 1)),0))), IF(R2="Yes", 0, IF(Q2="", 0, IFERROR(VALUE(MID(Q2, SEARCH("(",Q2)+1, 1)),0))))) | U2: =IF(A2="","", IF(T2>=5, "Priority 1 (Critical)", IF(T2>=3, "Priority 2 (Major)", IF(T2>=1, "Priority 3 (Minor)", "Pass/Fixed")))) | V2: =IF(A2="","", IF(T2>0, "FAIL", "PASS"))
A3: =IF('Equipment Information'!A3="","", 'Equipment Information'!A3) | B3: =IF('Equipment Information'!B3="","", 'Equipment Information'!B3) | C3: =IF('Equipment Information'!C3="","", 'Equipment Information'!C3) | E3: =IF(D3="","", IFERROR(VLOOKUP(D3, 'Hidden_Data'!M:N, 2, FALSE), "0")) | H3: =IF(G3="","", IFERROR(VLOOKUP(G3, 'Hidden_Data'!M:N, 2, FALSE), "0")) | K3: =IF(J3="","", IFERROR(VLOOKUP(J3, 'Hidden_Data'!M:N, 2, FALSE), "0")) | N3: =IF(M3="","", IFERROR(VLOOKUP(M3, 'Hidden_Data'!M:N, 2, FALSE), "0")) | Q3: =IF(P3="","", IFERROR(VLOOKUP(P3, 'Hidden_Data'!M:N, 2, FALSE), "0")) | T3: =IF(A3="","", SUM(IF(F3="Yes", 0, IF(E3="", 0, IFERROR(VALUE(MID(E3, SEARCH("(",E3)+1, 1)),0))), IF(I3="Yes", 0, IF(H3="", 0, IFERROR(VALUE(MID(H3, SEARCH("(",H3)+1, 1)),0))), IF(L3="Yes", 0, IF(K3="", 0, IFERROR(VALUE(MID(K3, SEARCH("(",K3)+1, 1)),0))), IF(O3="Yes", 0, IF(N3="", 0, IFERROR(VALUE(MID(N3, SEARCH("(",N3)+1, 1)),0))), IF(R3="Yes", 0, IF(Q3="", 0, IFERROR(VALUE(MID(Q3, SEARCH("(",Q3)+1, 1)),0))))) | U3: =IF(A3="","", IF(T3>=5, "Priority 1 (Critical)", IF(T3>=3, "Priority 2 (Major)", IF(T3>=1, "Priority 3 (Minor)", "Pass/Fixed")))) | V3: =IF(A3="","", IF(T3>0, "FAIL", "PASS"))
A4: =IF('Equipment Information'!A4="","", 'Equipment Information'!A4) | B4: =IF('Equipment Information'!B4="","", 'Equipment Information'!B4) | C4: =IF('Equipment Information'!C4="","", 'Equipment Information'!C4) | E4: =IF(D4="","", IFERROR(VLOOKUP(D4, 'Hidden_Data'!M:N, 2, FALSE), "0")) | H4: =IF(G4="","", IFERROR(VLOOKUP(G4, 'Hidden_Data'!M:N, 2, FALSE), "0")) | K4: =IF(J4="","", IFERROR(VLOOKUP(J4, 'Hidden_Data'!M:N, 2, FALSE), "0")) | N4: =IF(M4="","", IFERROR(VLOOKUP(M4, 'Hidden_Data'!M:N, 2, FALSE), "0")) | Q4: =IF(P4="","", IFERROR(VLOOKUP(P4, 'Hidden_Data'!M:N, 2, FALSE), "0")) | T4: =IF(A4="","", SUM(IF(F4="Yes", 0, IF(E4="", 0, IFERROR(VALUE(MID(E4, SEARCH("(",E4)+1, 1)),0))), IF(I4="Yes", 0, IF(H4="", 0, IFERROR(VALUE(MID(H4, SEARCH("(",H4)+1, 1)),0))), IF(L4="Yes", 0, IF(K4="", 0, IFERROR(VALUE(MID(K4, SEARCH("(",K4)+1, 1)),0))), IF(O4="Yes", 0, IF(N4="", 0, IFERROR(VALUE(MID(N4, SEARCH("(",N4)+1, 1)),0))), IF(R4="Yes", 0, IF(Q4="", 0, IFERROR(VALUE(MID(Q4, SEARCH("(",Q4)+1, 1)),0))))) | U4: =IF(A4="","", IF(T4>=5, "Priority 1 (Critical)", IF(T4>=3, "Priority 2 (Major)", IF(T4>=1, "Priority 3 (Minor)", "Pass/Fixed")))) | V4: =IF(A4="","", IF(T4>0, "FAIL", "PASS"))
A5: =IF('Equipment Information'!A5="","", 'Equipment Information'!A5) | B5: =IF('Equipment Information'!B5="","", 'Equipment Information'!B5) | C5: =IF('Equipment Information'!C5="","", 'Equipment Information'!C5) | E5: =IF(D5="","", IFERROR(VLOOKUP(D5, 'Hidden_Data'!M:N, 2, FALSE), "0")) | H5: =IF(G5="","", IFERROR(VLOOKUP(G5, 'Hidden_Data'!M:N, 2, FALSE), "0")) | K5: =IF(J5="","", IFERROR(VLOOKUP(J5, 'Hidden_Data'!M:N, 2, FALSE), "0")) | N5: =IF(M5="","", IFERROR(VLOOKUP(M5, 'Hidden_Data'!M:N, 2, FALSE), "0")) | Q5: =IF(P5="","", IFERROR(VLOOKUP(P5, 'Hidden_Data'!M:N, 2, FALSE), "0")) | T5: =IF(A5="","", SUM(IF(F5="Yes", 0, IF(E5="", 0, IFERROR(VALUE(MID(E5, SEARCH("(",E5)+1, 1)),0))), IF(I5="Yes", 0, IF(H5="", 0, IFERROR(VALUE(MID(H5, SEARCH("(",H5)+1, 1)),0))), IF(L5="Yes", 0, IF(K5="", 0, IFERROR(VALUE(MID(K5, SEARCH("(",K5)+1, 1)),0))), IF(O5="Yes", 0, IF(N5="", 0, IFERROR(VALUE(MID(N5, SEARCH("(",N5)+1, 1)),0))), IF(R5="Yes", 0, IF(Q5="", 0, IFERROR(VALUE(MID(Q5, SEARCH("(",Q5)+1, 1)),0))))) | U5: =IF(A5="","", IF(T5>=5, "Priority 1 (Critical)", IF(T5>=3, "Priority 2 (Major)", IF(T5>=1, "Priority 3 (Minor)", "Pass/Fixed")))) | V5: =IF(A5="","", IF(T5>0, "FAIL", "PASS"))
A6: =IF('Equipment Information'!A6="","", 'Equipment Information'!A6) | B6: =IF('Equipment Information'!B6="","", 'Equipment Information'!B6) | C6: =IF('Equipment Information'!C6="","", 'Equipment Information'!C6) | E6: =IF(D6="","", IFERROR(VLOOKUP(D6, 'Hidden_Data'!M:N, 2, FALSE), "0")) | H6: =IF(G6="","", IFERROR(VLOOKUP(G6, 'Hidden_Data'!M:N, 2, FALSE), "0")) | K6: =IF(J6="","", IFERROR(VLOOKUP(J6, 'Hidden_Data'!M:N, 2, FALSE), "0")) | N6: =IF(M6="","", IFERROR(VLOOKUP(M6, 'Hidden_Data'!M:N, 2, FALSE), "0")) | Q6: =IF(P6="","", IFERROR(VLOOKUP(P6, 'Hidden_Data'!M:N, 2, FALSE), "0")) | T6: =IF(A6="","", SUM(IF(F6="Yes", 0, IF(E6="", 0, IFERROR(VALUE(MID(E6, SEARCH("(",E6)+1, 1)),0))), IF(I6="Yes", 0, IF(H6="", 0, IFERROR(VALUE(MID(H6, SEARCH("(",H6)+1, 1)),0))), IF(L6="Yes", 0, IF(K6="", 0, IFERROR(VALUE(MID(K6, SEARCH("(",K6)+1, 1)),0))), IF(O6="Yes", 0, IF(N6="", 0, IFERROR(VALUE(MID(N6, SEARCH("(",N6)+1, 1)),0))), IF(R6="Yes", 0, IF(Q6="", 0, IFERROR(VALUE(MID(Q6, SEARCH("(",Q6)+1, 1)),0))))) | U6: =IF(A6="","", IF(T6>=5, "Priority 1 (Critical)", IF(T6>=3, "Priority 2 (Major)", IF(T6>=1, "Priority 3 (Minor)", "Pass/Fixed")))) | V6: =IF(A6="","", IF(T6>0, "FAIL", "PASS"))
A7: =IF('Equipment Information'!A7="","", 'Equipment Information'!A7) | B7: =IF('Equipment Information'!B7="","", 'Equipment Information'!B7) | C7: =IF('Equipment Information'!C7="","", 'Equipment Information'!C7) | E7: =IF(D7="","", IFERROR(VLOOKUP(D7, 'Hidden_Data'!M:N, 2, FALSE), "0")) | H7: =IF(G7="","", IFERROR(VLOOKUP(G7, 'Hidden_Data'!M:N, 2, FALSE), "0")) | K7: =IF(J7="","", IFERROR(VLOOKUP(J7, 'Hidden_Data'!M:N, 2, FALSE), "0")) | N7: =IF(M7="","", IFERROR(VLOOKUP(M7, 'Hidden_Data'!M:N, 2, FALSE), "0")) | Q7: =IF(P7="","", IFERROR(VLOOKUP(P7, 'Hidden_Data'!M:N, 2, FALSE), "0")) | T7: =IF(A7="","", SUM(IF(F7="Yes", 0, IF(E7="", 0, IFERROR(VALUE(MID(E7, SEARCH("(",E7)+1, 1)),0))), IF(I7="Yes", 0, IF(H7="", 0, IFERROR(VALUE(MID(H7, SEARCH("(",H7)+1, 1)),0))), IF(L7="Yes", 0, IF(K7="", 0, IFERROR(VALUE(MID(K7, SEARCH("(",K7)+1, 1)),0))), IF(O7="Yes", 0, IF(N7="", 0, IFERROR(VALUE(MID(N7, SEARCH("(",N7)+1, 1)),0))), IF(R7="Yes", 0, IF(Q7="", 0, IFERROR(VALUE(MID(Q7, SEARCH("(",Q7)+1, 1)),0))))) | U7: =IF(A7="","", IF(T7>=5, "Priority 1 (Critical)", IF(T7>=3, "Priority 2 (Major)", IF(T7>=1, "Priority 3 (Minor)", "Pass/Fixed")))) | V7: =IF(A7="","", IF(T7>0, "FAIL", "PASS"))
A8: =IF('Equipment Information'!A8="","", 'Equipment Information'!A8) | B8: =IF('Equipment Information'!B8="","", 'Equipment Information'!B8) | C8: =IF('Equipment Information'!C8="","", 'Equipment Information'!C8) | E8: =IF(D8="","", IFERROR(VLOOKUP(D8, 'Hidden_Data'!M:N, 2, FALSE), "0")) | H8: =IF(G8="","", IFERROR(VLOOKUP(G8, 'Hidden_Data'!M:N, 2, FALSE), "0")) | K8: =IF(J8="","", IFERROR(VLOOKUP(J8, 'Hidden_Data'!M:N, 2, FALSE), "0")) | N8: =IF(M8="","", IFERROR(VLOOKUP(M8, 'Hidden_Data'!M:N, 2, FALSE), "0")) | Q8: =IF(P8="","", IFERROR(VLOOKUP(P8, 'Hidden_Data'!M:N, 2, FALSE), "0")) | T8: =IF(A8="","", SUM(IF(F8="Yes", 0, IF(E8="", 0, IFERROR(VALUE(MID(E8, SEARCH("(",E8)+1, 1)),0))), IF(I8="Yes", 0, IF(H8="", 0, IFERROR(VALUE(MID(H8, SEARCH("(",H8)+1, 1)),0))), IF(L8="Yes", 0, IF(K8="", 0, IFERROR(VALUE(MID(K8, SEARCH("(",K8)+1, 1)),0))), IF(O8="Yes", 0, IF(N8="", 0, IFERROR(VALUE(MID(N8, SEARCH("(",N8)+1, 1)),0))), IF(R8="Yes", 0, IF(Q8="", 0, IFERROR(VALUE(MID(Q8, SEARCH("(",Q8)+1, 1)),0))))) | U8: =IF(A8="","", IF(T8>=5, "Priority 1 (Critical)", IF(T8>=3, "Priority 2 (Major)", IF(T8>=1, "Priority 3 (Minor)", "Pass/Fixed")))) | V8: =IF(A8="","", IF(T8>0, "FAIL", "PASS"))
A9: =IF('Equipment Information'!A9="","", 'Equipment Information'!A9) | B9: =IF('Equipment Information'!B9="","", 'Equipment Information'!B9) | C9: =IF('Equipment Information'!C9="","", 'Equipment Information'!C9) | E9: =IF(D9="","", IFERROR(VLOOKUP(D9, 'Hidden_Data'!M:N, 2, FALSE), "0")) | H9: =IF(G9="","", IFERROR(VLOOKUP(G9, 'Hidden_Data'!M:N, 2, FALSE), "0")) | K9: =IF(J9="","", IFERROR(VLOOKUP(J9, 'Hidden_Data'!M:N, 2, FALSE), "0")) | N9: =IF(M9="","", IFERROR(VLOOKUP(M9, 'Hidden_Data'!M:N, 2, FALSE), "0")) | Q9: =IF(P9="","", IFERROR(VLOOKUP(P9, 'Hidden_Data'!M:N, 2, FALSE), "0")) | T9: =IF(A9="","", SUM(IF(F9="Yes", 0, IF(E9="", 0, IFERROR(VALUE(MID(E9, SEARCH("(",E9)+1, 1)),0))), IF(I9="Yes", 0, IF(H9="", 0, IFERROR(VALUE(MID(H9, SEARCH("(",H9)+1, 1)),0))), IF(L9="Yes", 0, IF(K9="", 0, IFERROR(VALUE(MID(K9, SEARCH("(",K9)+1, 1)),0))), IF(O9="Yes", 0, IF(N9="", 0, IFERROR(VALUE(MID(N9, SEARCH("(",N9)+1, 1)),0))), IF(R9="Yes", 0, IF(Q9="", 0, IFERROR(VALUE(MID(Q9, SEARCH("(",Q9)+1, 1)),0))))) | U9: =IF(A9="","", IF(T9>=5, "Priority 1 (Critical)", IF(T9>=3, "Priority 2 (Major)", IF(T9>=1, "Priority 3 (Minor)", "Pass/Fixed")))) | V9: =IF(A9="","", IF(T9>0, "FAIL", "PASS"))
A10: =IF('Equipment Information'!A10="","", 'Equipment Information'!A10) | B10: =IF('Equipment Information'!B10="","", 'Equipment Information'!B10) | C10: =IF('Equipment Information'!C10="","", 'Equipment Information'!C10) | E10: =IF(D10="","", IFERROR(VLOOKUP(D10, 'Hidden_Data'!M:N, 2, FALSE), "0")) | H10: =IF(G10="","", IFERROR(VLOOKUP(G10, 'Hidden_Data'!M:N, 2, FALSE), "0")) | K10: =IF(J10="","", IFERROR(VLOOKUP(J10, 'Hidden_Data'!M:N, 2, FALSE), "0")) | N10: =IF(M10="","", IFERROR(VLOOKUP(M10, 'Hidden_Data'!M:N, 2, FALSE), "0")) | Q10: =IF(P10="","", IFERROR(VLOOKUP(P10, 'Hidden_Data'!M:N, 2, FALSE), "0")) | T10: =IF(A10="","", SUM(IF(F10="Yes", 0, IF(E10="", 0, IFERROR(VALUE(MID(E10, SEARCH("(",E10)+1, 1)),0))), IF(I10="Yes", 0, IF(H10="", 0, IFERROR(VALUE(MID(H10, SEARCH("(",H10)+1, 1)),0))), IF(L10="Yes", 0, IF(K10="", 0, IFERROR(VALUE(MID(K10, SEARCH("(",K10)+1, 1)),0))), IF(O10="Yes", 0, IF(N10="", 0, IFERROR(VALUE(MID(N10, SEARCH("(",N10)+1, 1)),0))), IF(R10="Yes", 0, IF(Q10="", 0, IFERROR(VALUE(MID(Q10, SEARCH("(",Q10)+1, 1)),0))))) | U10: =IF(A10="","", IF(T10>=5, "Priority 1 (Critical)", IF(T10>=3, "Priority 2 (Major)", IF(T10>=1, "Priority 3 (Minor)", "Pass/Fixed")))) | V10: =IF(A10="","", IF(T10>0, "FAIL", "PASS"))
A11: =IF('Equipment Information'!A11="","", 'Equipment Information'!A11) | B11: =IF('Equipment Information'!B11="","", 'Equipment Information'!B11) | C11: =IF('Equipment Information'!C11="","", 'Equipment Information'!C11) | E11: =IF(D11="","", IFERROR(VLOOKUP(D11, 'Hidden_Data'!M:N, 2, FALSE), "0")) | H11: =IF(G11="","", IFERROR(VLOOKUP(G11, 'Hidden_Data'!M:N, 2, FALSE), "0")) | K11: =IF(J11="","", IFERROR(VLOOKUP(J11, 'Hidden_Data'!M:N, 2, FALSE), "0")) | N11: =IF(M11="","", IFERROR(VLOOKUP(M11, 'Hidden_Data'!M:N, 2, FALSE), "0")) | Q11: =IF(P11="","", IFERROR(VLOOKUP(P11, 'Hidden_Data'!M:N, 2, FALSE), "0")) | T11: =IF(A11="","", SUM(IF(F11="Yes", 0, IF(E11="", 0, IFERROR(VALUE(MID(E11, SEARCH("(",E11)+1, 1)),0))), IF(I11="Yes", 0, IF(H11="", 0, IFERROR(VALUE(MID(H11, SEARCH("(",H11)+1, 1)),0))), IF(L11="Yes", 0, IF(K11="", 0, IFERROR(VALUE(MID(K11, SEARCH("(",K11)+1, 1)),0))), IF(O11="Yes", 0, IF(N11="", 0, IFERROR(VALUE(MID(N11, SEARCH("(",N11)+1, 1)),0))), IF(R11="Yes", 0, IF(Q11="", 0, IFERROR(VALUE(MID(Q11, SEARCH("(",Q11)+1, 1)),0))))) | U11: =IF(A11="","", IF(T11>=5, "Priority 1 (Critical)", IF(T11>=3, "Priority 2 (Major)", IF(T11>=1, "Priority 3 (Minor)", "Pass/Fixed")))) | V11: =IF(A11="","", IF(T11>0, "FAIL", "PASS"))
A12: =IF('Equipment Information'!A12="","", 'Equipment Information'!A12) | B12: =IF('Equipment Information'!B12="","", 'Equipment Information'!B12) | C12: =IF('Equipment Information'!C12="","", 'Equipment Information'!C12) | E12: =IF(D12="","", IFERROR(VLOOKUP(D12, 'Hidden_Data'!M:N, 2, FALSE), "0")) | H12: =IF(G12="","", IFERROR(VLOOKUP(G12, 'Hidden_Data'!M:N, 2, FALSE), "0")) | K12: =IF(J12="","", IFERROR(VLOOKUP(J12, 'Hidden_Data'!M:N, 2, FALSE), "0")) | N12: =IF(M12="","", IFERROR(VLOOKUP(M12, 'Hidden_Data'!M:N, 2, FALSE), "0")) | Q12: =IF(P12="","", IFERROR(VLOOKUP(P12, 'Hidden_Data'!M:N, 2, FALSE), "0")) | T12: =IF(A12="","", SUM(IF(F12="Yes", 0, IF(E12="", 0, IFERROR(VALUE(MID(E12, SEARCH("(",E12)+1, 1)),0))), IF(I12="Yes", 0, IF(H12="", 0, IFERROR(VALUE(MID(H12, SEARCH("(",H12)+1, 1)),0))), IF(L12="Yes", 0, IF(K12="", 0, IFERROR(VALUE(MID(K12, SEARCH("(",K12)+1, 1)),0))), IF(O12="Yes", 0, IF(N12="", 0, IFERROR(VALUE(MID(N12, SEARCH("(",N12)+1, 1)),0))), IF(R12="Yes", 0, IF(Q12="", 0, IFERROR(VALUE(MID(Q12, SEARCH("(",Q12)+1, 1)),0))))) | U12: =IF(A12="","", IF(T12>=5, "Priority 1 (Critical)", IF(T12>=3, "Priority 2 (Major)", IF(T12>=1, "Priority 3 (Minor)", "Pass/Fixed")))) | V12: =IF(A12="","", IF(T12>0, "FAIL", "PASS"))
A13: =IF('Equipment Information'!A13="","", 'Equipment Information'!A13) | B13: =IF('Equipment Information'!B13="","", 'Equipment Information'!B13) | C13: =IF('Equipment Information'!C13="","", 'Equipment Information'!C13) | E13: =IF(D13="","", IFERROR(VLOOKUP(D13, 'Hidden_Data'!M:N, 2, FALSE), "0")) | H13: =IF(G13="","", IFERROR(VLOOKUP(G13, 'Hidden_Data'!M:N, 2, FALSE), "0")) | K13: =IF(J13="","", IFERROR(VLOOKUP(J13, 'Hidden_Data'!M:N, 2, FALSE), "0")) | N13: =IF(M13="","", IFERROR(VLOOKUP(M13, 'Hidden_Data'!M:N, 2, FALSE), "0")) | Q13: =IF(P13="","", IFERROR(VLOOKUP(P13, 'Hidden_Data'!M:N, 2, FALSE), "0")) | T13: =IF(A13="","", SUM(IF(F13="Yes", 0, IF(E13="", 0, IFERROR(VALUE(MID(E13, SEARCH("(",E13)+1, 1)),0))), IF(I13="Yes", 0, IF(H13="", 0, IFERROR(VALUE(MID(H13, SEARCH("(",H13)+1, 1)),0))), IF(L13="Yes", 0, IF(K13="", 0, IFERROR(VALUE(MID(K13, SEARCH("(",K13)+1, 1)),0))), IF(O13="Yes", 0, IF(N13="", 0, IFERROR(VALUE(MID(N13, SEARCH("(",N13)+1, 1)),0))), IF(R13="Yes", 0, IF(Q13="", 0, IFERROR(VALUE(MID(Q13, SEARCH("(",Q13)+1, 1)),0))))) | U13: =IF(A13="","", IF(T13>=5, "Priority 1 (Critical)", IF(T13>=3, "Priority 2 (Major)", IF(T13>=1, "Priority 3 (Minor)", "Pass/Fixed")))) | V13: =IF(A13="","", IF(T13>0, "FAIL", "PASS"))
... A499: =IF('Equipment Information'!A499="","", 'Equipment Information'!A499) | B499: =IF('Equipment Information'!B499="","", 'Equipment Information'!B499) | C499: =IF('Equipment Information'!C499="","", 'Equipment Information'!C499) | E499: =IF(D499="","", IFERROR(VLOOKUP(D499, 'Hidden_Data'!M:N, 2, FALSE), "0")) | H499: =IF(G499="","", IFERROR(VLOOKUP(G499, 'Hidden_Data'!M:N, 2, FALSE), "0")) | K499: =IF(J499="","", IFERROR(VLOOKUP(J499, 'Hidden_Data'!M:N, 2, FALSE), "0")) | N499: =IF(M499="","", IFERROR(VLOOKUP(M499, 'Hidden_Data'!M:N, 2, FALSE), "0")) | Q499: =IF(P499="","", IFERROR(VLOOKUP(P499, 'Hidden_Data'!M:N, 2, FALSE), "0")) | T499: =IF(A499="","", SUM(IF(F499="Yes", 0, IF(E499="", 0, IFERROR(VALUE(MID(E499, SEARCH("(",E499)+1, 1)),0))), IF(I499="Yes", 0, IF(H499="", 0, IFERROR(VALUE(MID(H499, SEARCH("(",H499)+1, 1)),0))), IF(L499="Yes", 0, IF(K499="", 0, IFERROR(VALUE(MID(K499, SEARCH("(",K499)+1, 1)),0))), IF(O499="Yes", 0, IF(N499="", 0, IFERROR(VALUE(MID(N499, SEARCH("(",N499)+1, 1)),0))), IF(R499="Yes", 0, IF(Q499="", 0, IFERROR(VALUE(MID(Q499, SEARCH("(",Q499)+1, 1)),0))))) | U499: =IF(A499="","", IF(T499>=5, "Priority 1 (Critical)", IF(T499>=3, "Priority 2 (Major)", IF(T499>=1, "Priority 3 (Minor)", "Pass/Fixed")))) | V499: =IF(A499="","", IF(T499>0, "FAIL", "PASS"))

Sheet Infrared
A1: Tag | B1: Name | C1: Loc | D1: Phase (Point) | E1: Component | F1: Result | G1: Notes
A2: =IF('Equipment Information'!A2="","", 'Equipment Information'!A2) | B2: =IF('Equipment Information'!B2="","", 'Equipment Information'!B2) | C2: =IF('Equipment Information'!C2="","", 'Equipment Information'!C2) | F2: =IF(A2="","","N/A")
A3: =IF('Equipment Information'!A3="","", 'Equipment Information'!A3) | B3: =IF('Equipment Information'!B3="","", 'Equipment Information'!B3) | C3: =IF('Equipment Information'!C3="","", 'Equipment Information'!C3) | F3: =IF(A3="","","N/A")
A4: =IF('Equipment Information'!A4="","", 'Equipment Information'!A4) | B4: =IF('Equipment Information'!B4="","", 'Equipment Information'!B4) | C4: =IF('Equipment Information'!C4="","", 'Equipment Information'!C4) | F4: =IF(A4="","","N/A")
A5: =IF('Equipment Information'!A5="","", 'Equipment Information'!A5) | B5: =IF('Equipment Information'!B5="","", 'Equipment Information'!B5) | C5: =IF('Equipment Information'!C5="","", 'Equipment Information'!C5) | F5: =IF(A5="","","N/A")
A6: =IF('Equipment Information'!A6="","", 'Equipment Information'!A6) | B6: =IF('Equipment Information'!B6="","", 'Equipment Information'!B6) | C6: =IF('Equipment Information'!C6="","", 'Equipment Information'!C6) | F6: =IF(A6="","","N/A")
A7: =IF('Equipment Information'!A7="","", 'Equipment Information'!A7) | B7: =IF('Equipment Information'!B7="","", 'Equipment Information'!B7) | C7: =IF('Equipment Information'!C7="","", 'Equipment Information'!C7) | F7: =IF(A7="","","N/A")
A8: =IF('Equipment Information'!A8="","", 'Equipment Information'!A8) | B8: =IF('Equipment Information'!B8="","", 'Equipment Information'!B8) | C8: =IF('Equipment Information'!C8="","", 'Equipment Information'!C8) | F8: =IF(A8="","","N/A")
A9: =IF('Equipment Information'!A9="","", 'Equipment Information'!A9) | B9: =IF('Equipment Information'!B9="","", 'Equipment Information'!B9) | C9: =IF('Equipment Information'!C9="","", 'Equipment Information'!C9) | F9: =IF(A9="","","N/A")
A10: =IF('Equipment Information'!A10="","", 'Equipment Information'!A10) | B10: =IF('Equipment Information'!B10="","", 'Equipment Information'!B10) | C10: =IF('Equipment Information'!C10="","", 'Equipment Information'!C10) | F10: =IF(A10="","","N/A")
A11: =IF('Equipment Information'!A11="","", 'Equipment Information'!A11) | B11: =IF('Equipment Information'!B11="","", 'Equipment Information'!B11) | C11: =IF('Equipment Information'!C11="","", 'Equipment Information'!C11) | F11: =IF(A11="","","N/A")
A12: =IF('Equipment Information'!A12="","", 'Equipment Information'!A12) | B12: =IF('Equipment Information'!B12="","", 'Equipment Information'!B12) | C12: =IF('Equipment Information'!C12="","", 'Equipment Information'!C12) | F12: =IF(A12="","","N/A")
A13: =IF('Equipment Information'!A13="","", 'Equipment Information'!A13) | B13: =IF('Equipment Information'!B13="","", 'Equipment Information'!B13) | C13: =IF('Equipment Information'!C13="","", 'Equipment Information'!C13) | F13: =IF(A13="","","N/A")
... A499: =IF('Equipment Information'!A499="","", 'Equipment Information'!A499) | B499: =IF('Equipment Information'!B499="","", 'Equipment Information'!B499) | C499: =IF('Equipment Information'!C499="","", 'Equipment Information'!C499) | F499: =IF(A499="","","N/A")

Sheet Ultrasonic
A1: Tag | B1: Name | C1: Loc | D1: Component | E1: Failure Mode | F1: dB Level | G1: Result | H1: Notes
A2: =IF('Equipment Information'!A2="","", 'Equipment Information'!A2) | B2: =IF('Equipment Information'!B2="","", 'Equipment Information'!B2) | C2: =IF('Equipment Information'!C2="","", 'Equipment Information'!C2) | G2: =IF(A2="","","N/A")
A3: =IF('Equipment Information'!A3="","", 'Equipment Information'!A3) | B3: =IF('Equipment Information'!B3="","", 'Equipment Information'!B3) | C3: =IF('Equipment Information'!C3="","", 'Equipment Information'!C3) | G3: =IF(A3="","","N/A")
A4: =IF('Equipment Information'!A4="","", 'Equipment Information'!A4) | B4: =IF('Equipment Information'!B4="","", 'Equipment Information'!B4) | C4: =IF('Equipment Information'!C4="","", 'Equipment Information'!C4) | G4: =IF(A4="","","N/A")
A5: =IF('Equipment Information'!A5="","", 'Equipment Information'!A5) | B5: =IF('Equipment Information'!B5="","", 'Equipment Information'!B5) | C5: =IF('Equipment Information'!C5="","", 'Equipment Information'!C5) | G5: =IF(A5="","","N/A")
A6: =IF('Equipment Information'!A6="","", 'Equipment Information'!A6) | B6: =IF('Equipment Information'!B6="","", 'Equipment Information'!B6) | C6: =IF('Equipment Information'!C6="","", 'Equipment Information'!C6) | G6: =IF(A6="","","N/A")
A7: =IF('Equipment Information'!A7="","", 'Equipment Information'!A7) | B7: =IF('Equipment Information'!B7="","", 'Equipment Information'!B7) | C7: =IF('Equipment Information'!C7="","", 'Equipment Information'!C7) | G7: =IF(A7="","","N/A")
A8: =IF('Equipment Information'!A8="","", 'Equipment Information'!A8) | B8: =IF('Equipment Information'!B8="","", 'Equipment Information'!B8) | C8: =IF('Equipment Information'!C8="","", 'Equipment Information'!C8) | G8: =IF(A8="","","N/A")
A9: =IF('Equipment Information'!A9="","", 'Equipment Information'!A9) | B9: =IF('Equipment Information'!B9="","", 'Equipment Information'!B9) | C9: =IF('Equipment Information'!C9="","", 'Equipment Information'!C9) | G9: =IF(A9="","","N/A")
A10: =IF('Equipment Information'!A10="","", 'Equipment Information'!A10) | B10: =IF('Equipment Information'!B10="","", 'Equipment Information'!B10) | C10: =IF('Equipment Information'!C10="","", 'Equipment Information'!C10) | G10: =IF(A10="","","N/A")
A11: =IF('Equipment Information'!A11="","", 'Equipment Information'!A11) | B11: =IF('Equipment Information'!B11="","", 'Equipment Information'!B11) | C11: =IF('Equipment Information'!C11="","", 'Equipment Information'!C11) | G11: =IF(A11="","","N/A")
A12: =IF('Equipment Information'!A12="","", 'Equipment Information'!A12) | B12: =IF('Equipment Information'!B12="","", 'Equipment Information'!B12) | C12: =IF('Equipment Information'!C12="","", 'Equipment Information'!C12) | G12: =IF(A12="","","N/A")
A13: =IF('Equipment Information'!A13="","", 'Equipment Information'!A13) | B13: =IF('Equipment Information'!B13="","", 'Equipment Information'!B13) | C13: =IF('Equipment Information'!C13="","", 'Equipment Information'!C13) | G13: =IF(A13="","","N/A")
... A499: =IF('Equipment Information'!A499="","", 'Equipment Information'!A499) | B499: =IF('Equipment Information'!B499="","", 'Equipment Information'!B499) | C499: =IF('Equipment Information'!C499="","", 'Equipment Information'!C499) | G499: =IF(A499="","","N/A")

Sheet Energized Data
A1: Tag | B1: Name | C1: Loc | D1: Phase | E1: Wire | F1: V-AB | G1: V-BC | H1: V-CA | I1: AvgV | J1: V-Imb% | K1: A-A | L1: A-B | M1: A-C | N1: AvgA | O1: Rated Amps | P1: OCPD | Q1: Load% | R1: I-Imb% | S1: Analysis | T1: Summary
A2: =IF('Equipment Information'!A2="","", 'Equipment Information'!A2) | B2: =IF('Equipment Information'!B2="","", 'Equipment Information'!B2) | C2: =IF('Equipment Information'!C2="","", 'Equipment Information'!C2) | I2: =IF(COUNT(F2:H2)<2,"",AVERAGE(F2:H2)) | J2: =IF(I2="","",MAX(ABS(F2-I2),ABS(G2-I2),ABS(H2-I2))/I2) | N2: =IF(COUNT(K2:M2)<2,"",AVERAGE(K2:M2)) | R2: =IF(N2="","",MAX(ABS(K2-N2),ABS(L2-N2),ABS(M2-N2))/N2) | S2: =IF(A2="","",IF(AND(F2="",K2=""),"N/A",IF(AND(J2="",R2=""),"Insufficient Load Data",IF(AND(J2>0.03,R2>0.15),"Voltage & Current Imbalance",IF(J2>0.03,"Voltage Imbalance",IF(R2>0.15,"Current Imbalance","No Imbalances Detected"))))) | T2: =IF(A2="","",IF(AND(F2="",K2=""),"N/A",IF(OR(J2>0.03,R2>0.15),"Imbalance","Pass")))
A3: =IF('Equipment Information'!A3="","", 'Equipment Information'!A3) | B3: =IF('Equipment Information'!B3="","", 'Equipment Information'!B3) | C3: =IF('Equipment Information'!C3="","", 'Equipment Information'!C3) | I3: =IF(COUNT(F3:H3)<2,"",AVERAGE(F3:H3)) | J3: =IF(I3="","",MAX(ABS(F3-I3),ABS(G3-I3),ABS(H3-I3))/I3) | N3: =IF(COUNT(K3:M3)<2,"",AVERAGE(K3:M3)) | R3: =IF(N3="","",MAX(ABS(K3-N3),ABS(L3-N3),ABS(M3-N3))/N3) | S3: =IF(A3="","",IF(AND(F3="",K3=""),"N/A",IF(AND(J3="",R3=""),"Insufficient Load Data",IF(AND(J3>0.03,R3>0.15),"Voltage & Current Imbalance",IF(J3>0.03,"Voltage Imbalance",IF(R3>0.15,"Current Imbalance","No Imbalances Detected"))))) | T3: =IF(A3="","",IF(AND(F3="",K3=""),"N/A",IF(OR(J3>0.03,R3>0.15),"Imbalance","Pass")))
A4: =IF('Equipment Information'!A4="","", 'Equipment Information'!A4) | B4: =IF('Equipment Information'!B4="","", 'Equipment Information'!B4) | C4: =IF('Equipment Information'!C4="","", 'Equipment Information'!C4) | I4: =IF(COUNT(F4:H4)<2,"",AVERAGE(F4:H4)) | J4: =IF(I4="","",MAX(ABS(F4-I4),ABS(G4-I4),ABS(H4-I4))/I4) | N4: =IF(COUNT(K4:M4)<2,"",AVERAGE(K4:M4)) | R4: =IF(N4="","",MAX(ABS(K4-N4),ABS(L4-N4),ABS(M4-N4))/N4) | S4: =IF(A4="","",IF(AND(F4="",K4=""),"N/A",IF(AND(J4="",R4=""),"Insufficient Load Data",IF(AND(J4>0.03,R4>0.15),"Voltage & Current Imbalance",IF(J4>0.03,"Voltage Imbalance",IF(R4>0.15,"Current Imbalance","No Imbalances Detected"))))) | T4: =IF(A4="","",IF(AND(F4="",K4=""),"N/A",IF(OR(J4>0.03,R4>0.15),"Imbalance","Pass")))
A5: =IF('Equipment Information'!A5="","", 'Equipment Information'!A5) | B5: =IF('Equipment Information'!B5="","", 'Equipment Information'!B5) | C5: =IF('Equipment Information'!C5="","", 'Equipment Information'!C5) | I5: =IF(COUNT(F5:H5)<2,"",AVERAGE(F5:H5)) | J5: =IF(I5="","",MAX(ABS(F5-I5),ABS(G5-I5),ABS(H5-I5))/I5) | N5: =IF(COUNT(K5:M5)<2,"",AVERAGE(K5:M5)) | R5: =IF(N5="","",MAX(ABS(K5-N5),ABS(L5-N5),ABS(M5-N5))/N5) | S5: =IF(A5="","",IF(AND(F5="",K5=""),"N/A",IF(AND(J5="",R5=""),"Insufficient Load Data",IF(AND(J5>0.03,R5>0.15),"Voltage & Current Imbalance",IF(J5>0.03,"Voltage Imbalance",IF(R5>0.15,"Current Imbalance","No Imbalances Detected"))))) | T5: =IF(A5="","",IF(AND(F5="",K5=""),"N/A",IF(OR(J5>0.03,R5>0.15),"Imbalance","Pass")))
A6: =IF('Equipment Information'!A6="","", 'Equipment Information'!A6) | B6: =IF('Equipment Information'!B6="","", 'Equipment Information'!B6) | C6: =IF('Equipment Information'!C6="","", 'Equipment Information'!C6) | I6: =IF(COUNT(F6:H6)<2,"",AVERAGE(F6:H6)) | J6: =IF(I6="","",MAX(ABS(F6-I6),ABS(G6-I6),ABS(H6-I6))/I6) | N6: =IF(COUNT(K6:M6)<2,"",AVERAGE(K6:M6)) | R6: =IF(N6="","",MAX(ABS(K6-N6),ABS(L6-N6),ABS(M6-N6))/N6) | S6: =IF(A6="","",IF(AND(F6="",K6=""),"N/A",IF(AND(J6="",R6=""),"Insufficient Load Data",IF(AND(J6>0.03,R6>0.15),"Voltage & Current Imbalance",IF(J6>0.03,"Voltage Imbalance",IF(R6>0.15,"Current Imbalance","No Imbalances Detected"))))) | T6: =IF(A6="","",IF(AND(F6="",K6=""),"N/A",IF(OR(J6>0.03,R6>0.15),"Imbalance","Pass")))
A7: =IF('Equipment Information'!A7="","", 'Equipment Information'!A7) | B7: =IF('Equipment Information'!B7="","", 'Equipment Information'!B7) | C7: =IF('Equipment Information'!C7="","", 'Equipment Information'!C7) | I7: =IF(COUNT(F7:H7)<2,"",AVERAGE(F7:H7)) | J7: =IF(I7="","",MAX(ABS(F7-I7),ABS(G7-I7),ABS(H7-I7))/I7) | N7: =IF(COUNT(K7:M7)<2,"",AVERAGE(K7:M7)) | R7: =IF(N7="","",MAX(ABS(K7-N7),ABS(L7-N7),ABS(M7-N7))/N7) | S7: =IF(A7="","",IF(AND(F7="",K7=""),"N/A",IF(AND(J7="",R7=""),"Insufficient Load Data",IF(AND(J7>0.03,R7>0.15),"Voltage & Current Imbalance",IF(J7>0.03,"Voltage Imbalance",IF(R7>0.15,"Current Imbalance","No Imbalances Detected"))))) | T7: =IF(A7="","",IF(AND(F7="",K7=""),"N/A",IF(OR(J7>0.03,R7>0.15),"Imbalance","Pass")))
A8: =IF('Equipment Information'!A8="","", 'Equipment Information'!A8) | B8: =IF('Equipment Information'!B8="","", 'Equipment Information'!B8) | C8: =IF('Equipment Information'!C8="","", 'Equipment Information'!C8) | I8: =IF(COUNT(F8:H8)<2,"",AVERAGE(F8:H8)) | J8: =IF(I8="","",MAX(ABS(F8-I8),ABS(G8-I8),ABS(H8-I8))/I8) | N8: =IF(COUNT(K8:M8)<2,"",AVERAGE(K8:M8)) | R8: =IF(N8="","",MAX(ABS(K8-N8),ABS(L8-N8),ABS(M8-N8))/N8) | S8: =IF(A8="","",IF(AND(F8="",K8=""),"N/A",IF(AND(J8="",R8=""),"Insufficient Load Data",IF(AND(J8>0.03,R8>0.15),"Voltage & Current Imbalance",IF(J8>0.03,"Voltage Imbalance",IF(R8>0.15,"Current Imbalance","No Imbalances Detected"))))) | T8: =IF(A8="","",IF(AND(F8="",K8=""),"N/A",IF(OR(J8>0.03,R8>0.15),"Imbalance","Pass")))
A9: =IF('Equipment Information'!A9="","", 'Equipment Information'!A9) | B9: =IF('Equipment Information'!B9="","", 'Equipment Information'!B9) | C9: =IF('Equipment Information'!C9="","", 'Equipment Information'!C9) | I9: =IF(COUNT(F9:H9)<2,"",AVERAGE(F9:H9)) | J9: =IF(I9="","",MAX(ABS(F9-I9),ABS(G9-I9),ABS(H9-I9))/I9) | N9: =IF(COUNT(K9:M9)<2,"",AVERAGE(K9:M9)) | R9: =IF(N9="","",MAX(ABS(K9-N9),ABS(L9-N9),ABS(M9-N9))/N9) | S9: =IF(A9="","",IF(AND(F9="",K9=""),"N/A",IF(AND(J9="",R9=""),"Insufficient Load Data",IF(AND(J9>0.03,R9>0.15),"Voltage & Current Imbalance",IF(J9>0.03,"Voltage Imbalance",IF(R9>0.15,"Current Imbalance","No Imbalances Detected"))))) | T9: =IF(A9="","",IF(AND(F9="",K9=""),"N/A",IF(OR(J9>0.03,R9>0.15),"Imbalance","Pass")))
A10: =IF('Equipment Information'!A10="","", 'Equipment Information'!A10) | B10: =IF('Equipment Information'!B10="","", 'Equipment Information'!B10) | C10: =IF('Equipment Information'!C10="","", 'Equipment Information'!C10) | I10: =IF(COUNT(F10:H10)<2,"",AVERAGE(F10:H10)) | J10: =IF(I10="","",MAX(ABS(F10-I10),ABS(G10-I10),ABS(H10-I10))/I10) | N10: =IF(COUNT(K10:M10)<2,"",AVERAGE(K10:M10)) | R10: =IF(N10="","",MAX(ABS(K10-N10),ABS(L10-N10),ABS(M10-N10))/N10) | S10: =IF(A10="","",IF(AND(F10="",K10=""),"N/A",IF(AND(J10="",R10=""),"Insufficient Load Data",IF(AND(J10>0.03,R10>0.15),"Voltage & Current Imbalance",IF(J10>0.03,"Voltage Imbalance",IF(R10>0.15,"Current Imbalance","No Imbalances Detected"))))) | T10: =IF(A10="","",IF(AND(F10="",K10=""),"N/A",IF(OR(J10>0.03,R10>0.15),"Imbalance","Pass")))
A11: =IF('Equipment Information'!A11="","", 'Equipment Information'!A11) | B11: =IF('Equipment Information'!B11="","", 'Equipment Information'!B11) | C11: =IF('Equipment Information'!C11="","", 'Equipment Information'!C11) | I11: =IF(COUNT(F11:H11)<2,"",AVERAGE(F11:H11)) | J11: =IF(I11="","",MAX(ABS(F11-I11),ABS(G11-I11),ABS(H11-I11))/I11) | N11: =IF(COUNT(K11:M11)<2,"",AVERAGE(K11:M11)) | R11: =IF(N11="","",MAX(ABS(K11-N11),ABS(L11-N11),ABS(M11-N11))/N11) | S11: =IF(A11="","",IF(AND(F11="",K11=""),"N/A",IF(AND(J11="",R11=""),"Insufficient Load Data",IF(AND(J11>0.03,R11>0.15),"Voltage & Current Imbalance",IF(J11>0.03,"Voltage Imbalance",IF(R11>0.15,"Current Imbalance","No Imbalances Detected"))))) | T11: =IF(A11="","",IF(AND(F11="",K11=""),"N/A",IF(OR(J11>0.03,R11>0.15),"Imbalance","Pass")))
A12: =IF('Equipment Information'!A12="","", 'Equipment Information'!A12) | B12: =IF('Equipment Information'!B12="","", 'Equipment Information'!B12) | C12: =IF('Equipment Information'!C12="","", 'Equipment Information'!C12) | I12: =IF(COUNT(F12:H12)<2,"",AVERAGE(F12:H12)) | J12: =IF(I12="","",MAX(ABS(F12-I12),ABS(G12-I12),ABS(H12-I12))/I12) | N12: =IF(COUNT(K12:M12)<2,"",AVERAGE(K12:M12)) | R12: =IF(N12="","",MAX(ABS(K12-N12),ABS(L12-N12),ABS(M12-N12))/N12) | S12: =IF(A12="","",IF(AND(F12="",K12=""),"N/A",IF(AND(J12="",R12=""),"Insufficient Load Data",IF(AND(J12>0.03,R12>0.15),"Voltage & Current Imbalance",IF(J12>0.03,"Voltage Imbalance",IF(R12>0.15,"Current Imbalance","No Imbalances Detected"))))) | T12: =IF(A12="","",IF(AND(F12="",K12=""),"N/A",IF(OR(J12>0.03,R12>0.15),"Imbalance","Pass")))
A13: =IF('Equipment Information'!A13="","", 'Equipment Information'!A13) | B13: =IF('Equipment Information'!B13="","", 'Equipment Information'!B13) | C13: =IF('Equipment Information'!C13="","", 'Equipment Information'!C13) | I13: =IF(COUNT(F13:H13)<2,"",AVERAGE(F13:H13)) | J13: =IF(I13="","",MAX(ABS(F13-I13),ABS(G13-I13),ABS(H13-I13))/I13) | N13: =IF(COUNT(K13:M13)<2,"",AVERAGE(K13:M13)) | R13: =IF(N13="","",MAX(ABS(K13-N13),ABS(L13-N13),ABS(M13-N13))/N13) | S13: =IF(A13="","",IF(AND(F13="",K13=""),"N/A",IF(AND(J13="",R13=""),"Insufficient Load Data",IF(AND(J13>0.03,R13>0.15),"Voltage & Current Imbalance",IF(J13>0.03,"Voltage Imbalance",IF(R13>0.15,"Current Imbalance","No Imbalances Detected"))))) | T13: =IF(A13="","",IF(AND(F13="",K13=""),"N/A",IF(OR(J13>0.03,R13>0.15),"Imbalance","Pass")))
... A499: =IF('Equipment Information'!A499="","", 'Equipment Information'!A499) | B499: =IF('Equipment Information'!B499="","", 'Equipment Information'!B499) | C499: =IF('Equipment Information'!C499="","", 'Equipment Information'!C499) | I499: =IF(COUNT(F499:H499)<2,"",AVERAGE(F499:H499)) | J499: =IF(I499="","",MAX(ABS(F499-I499),ABS(G499-I499),ABS(H499-I499))/I499) | N499: =IF(COUNT(K499:M499)<2,"",AVERAGE(K499:M499)) | R499: =IF(N499="","",MAX(ABS(K499-N499),ABS(L499-N499),ABS(M499-N499))/N499) | S499: =IF(A499="","",IF(AND(F499="",K499=""),"N/A",IF(AND(J499="",R499=""),"Insufficient Load Data",IF(AND(J499>0.03,R499>0.15),"Voltage & Current Imbalance",IF(J499>0.03,"Voltage Imbalance",IF(R499>0.15,"Current Imbalance","No Imbalances Detected"))))) | T499: =IF(A499="","",IF(AND(F499="",K499=""),"N/A",IF(OR(J499>0.03,R499>0.15),"Imbalance","Pass")))

Sheet Hidden_Data
A1: 480V Primary Transformer - Oil Filled <5000kVA | B1: PASS | C1: Yes | D1: Life Safety (High) | E1: Verified (Current) | H1: Single Phase | I1: 2-Wire | J1: Breaker (Line) | K1: Arcing | L1: A-Phase | M1: Condition of Maintenance / AF Labeling and IR Loading | N1: Critical (5pts)
A2: 480V/208V/120V Transformer - Dry <250 kva | B2: FAIL | C2: No | D2: Production Critical (High) | E2: Overdue (<2 Cycles) | H2: Three Phase | I2: 3-Wire | J2: Breaker (Load) | K2: Tracking | L2: B-Phase | M2: NEC 110.16 & NFPA 70E 130.5(H) Arc Flash Labeling & Study Validation | N2: Critical (5pts)
A3: 480V/208V/120V Transformer - Dry >=250 kva | B3: MONITOR | D3: Support/Utility (Med) | E3: Critical (>2 Cycles/Unknown) | H3: DC | I3: 4-Wire | J3: Bus Joint | K3: Corona | L3: C-Phase | M3: XFMR Cond. of Maint. / AF Labeling and IR Loading | N3: Critical (5pts)
A4: Auto Transfer Switch <=400A | B4: N/A | D4: General/Comfort (Low) | J4: Cable Term | K4: Vibration | L4: Neutral | M4: Equipment Cleanliness and Maintenance Condition | N4: Major (3pts)
A5: Auto Transfer Switch >400A | D5: Unknown | J5: Fuse Clip | K5: Mech Loose | L5: Multi-Phase | M5: VFD with Undefeatable Interlock Handle | N5: Minor (1pt)
A6: Branch Circuit Panel <=400A | J6: Lug/Term | K6: Motor Bearing | L6: Ground | M6: NEC 110.3(B) - (Screws/Clips) Listing and Labeling | N6: Minor (1pt)
A7: Bus Duct - Vertical or Horizontal (Per 10ft) | J7: Switchgear/Bus | M7: NEC 110.3(B) / 408.7 - Combined Hardware/KO Seal | N7: Major (3pts)
A8: Distribution Panel Single Front >=600A | J8: Transformer | M8: NEC 110.12 - Mechanical Execution of Work | N8: Minor (1pt)
A9: Distribution Switchboard Multi Cover (Per Section) | J9: VFD | M9: NEC 110.14(A) - Terminations | N9: Major (3pts)
A10: Individual Motor Starter | M10: NEC 110.16(B) - Arc Flash Hazard Labeling (2026 Expansion) | N10: Critical (5pts)
A11: Individual Combination Motor Starter | M11: NEC 110.14(D) - Torque Requirements | N11: Major (3pts)
A12: Individual Disconnect Switch | M12: NEC 110.21(B) - Labeling Methods & Durability | N12: Minor (1pt)
A13: Individual Molded Case Breaker >=600A | M13: NEC 110.22(A) - ID of Disconnecting Means | N13: Minor (1pt)
A14: Lighting Contactor <=50 hp | M14: NEC 110.24 - Available Fault Current Labeling | N14: Major (3pts)
A15: MCC: Combination Motor Starters | M15: NEC 110.26 - Working Space | N15: Critical (5pts)
A16: MCC: Individual Disconnect Switch | M16: NEC 110.26(A)(4) - Working Space & Egress (90-Degree Door) | N16: Critical (5pts)
A17: MCC: Molded Case Breaker | M17: NEC 110.26(E) Dedicated Electrical Equipment Space | N17: Major (3pts)
A18: MCC: Motor Starters | M18: NEC 110.26(C)(2),(3) - Elec Rm Panic Hardware | N18: Critical (5pts)
A19: Motor Control Center (Per vertical section) | M19: NEC 110.26(C)(2),(3) - Small Electric Room Egress | N19: Major (3pts)
A20: Switchboard Molded Case Breakers >=600A | M20: NFPA 70E 130.4 / NEC 110.27(A) - Exposed Live Parts | N20: Critical (5pts)
A21: Switchgear - Incoming Main Service (Per Section) | M21: NEC 240.4 / 240.6(A) - OCPD Sizing /Stand Ratings | N21: Critical (5pts)
... A27: Wire Trough/Large Junction Boxes | M27: NEC 250.122 Equipment Grounding Conductor Sizing | N27: Major (3pts)
M28: NEC 300.4 Protect Phys Dmg (Bush/Sleeve/Edge) | N28: Major (3pts)
M29: NEC 300.5(D) - Underground Raceway / Cover Depth | N29: Major (3pts)
M30: NEC 300.11 Support Race & Cables / Ceiling Grid | N30: Minor (1pt)
M31: NEC 300.14 - Free Conductor Length | N31: Minor (1pt)
M32: NEC 312.5(C) - Cable Entry (NM/MC into Panels) | N32: Major (3pts)
M33: NEC 312.8 Panelboard Wire Fill / Splicing in Cabinets | N33: Major (3pts)
M34: NEC 348.30(A) - FMC Support and Securement | N34: Minor (1pt)
M35: NEC 350.30(A) - LFMC Support and Securement | N35: Minor (1pt)
M36: NEC 358.30(A) - EMT Support and Securement | N36: Minor (1pt)
M37: NEC 404.8 - Switch Mounting | N37: Major (3pts)
M38: NEC 406.5 - Receptacle Faceplate / Mounting | N38: Minor (1pt)
M39: NEC 408.4(A) - Circuit Identification | N39: Minor (1pt)
... M166: NFPA 70B 12.2 - Draw-Out Element Racking Mechanism Defective | N166: Critical (5pts)

Sheet Insulation
A1: Tag | B1: Name | C1: Loc | D1: TestV | E1: Ph-Ph | F1: Ph-G | G1: PI | H1: Temp | I1: Result | J1: Notes
A2: =IF('Equipment Information'!A2="","", 'Equipment Information'!A2) | B2: =IF('Equipment Information'!B2="","", 'Equipment Information'!B2) | C2: =IF('Equipment Information'!C2="","", 'Equipment Information'!C2) | I2: =IF(A2="","","N/A")
A3: =IF('Equipment Information'!A3="","", 'Equipment Information'!A3) | B3: =IF('Equipment Information'!B3="","", 'Equipment Information'!B3) | C3: =IF('Equipment Information'!C3="","", 'Equipment Information'!C3) | I3: =IF(A3="","","N/A")
A4: =IF('Equipment Information'!A4="","", 'Equipment Information'!A4) | B4: =IF('Equipment Information'!B4="","", 'Equipment Information'!B4) | C4: =IF('Equipment Information'!C4="","", 'Equipment Information'!C4) | I4: =IF(A4="","","N/A")
A5: =IF('Equipment Information'!A5="","", 'Equipment Information'!A5) | B5: =IF('Equipment Information'!B5="","", 'Equipment Information'!B5) | C5: =IF('Equipment Information'!C5="","", 'Equipment Information'!C5) | I5: =IF(A5="","","N/A")
A6: =IF('Equipment Information'!A6="","", 'Equipment Information'!A6) | B6: =IF('Equipment Information'!B6="","", 'Equipment Information'!B6) | C6: =IF('Equipment Information'!C6="","", 'Equipment Information'!C6) | I6: =IF(A6="","","N/A")
A7: =IF('Equipment Information'!A7="","", 'Equipment Information'!A7) | B7: =IF('Equipment Information'!B7="","", 'Equipment Information'!B7) | C7: =IF('Equipment Information'!C7="","", 'Equipment Information'!C7) | I7: =IF(A7="","","N/A")
A8: =IF('Equipment Information'!A8="","", 'Equipment Information'!A8) | B8: =IF('Equipment Information'!B8="","", 'Equipment Information'!B8) | C8: =IF('Equipment Information'!C8="","", 'Equipment Information'!C8) | I8: =IF(A8="","","N/A")
A9: =IF('Equipment Information'!A9="","", 'Equipment Information'!A9) | B9: =IF('Equipment Information'!B9="","", 'Equipment Information'!B9) | C9: =IF('Equipment Information'!C9="","", 'Equipment Information'!C9) | I9: =IF(A9="","","N/A")
A10: =IF('Equipment Information'!A10="","", 'Equipment Information'!A10) | B10: =IF('Equipment Information'!B10="","", 'Equipment Information'!B10) | C10: =IF('Equipment Information'!C10="","", 'Equipment Information'!C10) | I10: =IF(A10="","","N/A")
A11: =IF('Equipment Information'!A11="","", 'Equipment Information'!A11) | B11: =IF('Equipment Information'!B11="","", 'Equipment Information'!B11) | C11: =IF('Equipment Information'!C11="","", 'Equipment Information'!C11) | I11: =IF(A11="","","N/A")
A12: =IF('Equipment Information'!A12="","", 'Equipment Information'!A12) | B12: =IF('Equipment Information'!B12="","", 'Equipment Information'!B12) | C12: =IF('Equipment Information'!C12="","", 'Equipment Information'!C12) | I12: =IF(A12="","","N/A")
A13: =IF('Equipment Information'!A13="","", 'Equipment Information'!A13) | B13: =IF('Equipment Information'!B13="","", 'Equipment Information'!B13) | C13: =IF('Equipment Information'!C13="","", 'Equipment Information'!C13) | I13: =IF(A13="","","N/A")
... A499: =IF('Equipment Information'!A499="","", 'Equipment Information'!A499) | B499: =IF('Equipment Information'!B499="","", 'Equipment Information'!B499) | C499: =IF('Equipment Information'!C499="","", 'Equipment Information'!C499) | I499: =IF(A499="","","N/A")

Sheet DLRO
A1: Tag | B1: Name | C1: Loc | D1: Ph-A | E1: Ph-B | F1: Ph-C | G1: Dev% | H1: Result | I1: Notes
A2: =IF('Equipment Information'!A2="","", 'Equipment Information'!A2) | B2: =IF('Equipment Information'!B2="","", 'Equipment Information'!B2) | C2: =IF('Equipment Information'!C2="","", 'Equipment Information'!C2) | H2: =IF(A2="","","N/A")
A3: =IF('Equipment Information'!A3="","", 'Equipment Information'!A3) | B3: =IF('Equipment Information'!B3="","", 'Equipment Information'!B3) | C3: =IF('Equipment Information'!C3="","", 'Equipment Information'!C3) | H3: =IF(A3="","","N/A")
