Workbook

Sheet Bldgs & Rooms
A1: If there are not multiple buildings, do not modify this column | B1: Modify this column to name each "room" or "location" where equipment is located, using the customer's description
A2: Main Bldg.
A3: Main Bldg.
A4: Main Bldg.
A5: Main Bldg.
A6: Main Bldg.
A7: Main Bldg.
A8: Main Bldg.
A9: Main Bldg.
A10: Main Bldg.
A11: Main Bldg.
A12: Main Bldg.
A13: Main Bldg.
... A31: Main Bldg.

Sheet Hours
A1: 600 Volt and below | B1: Full EPM | C1: De-energized Maint. | D1: IR | E1: Ultrasonic | F1: A-F Collection | G1: Pri.Breaker | H1: Sec. Breaker | I1: PwrFact (partial) | J1: PwrFact (xfmr/CB) | K1: Panel Schd. | L1: Oil Sample | M1: Basic EPM
A2: Switchgear - Incoming Main Service (Per Section) | B2: 2 | C2: 3.4833 | D2: 0.5833 | E2: 0.25 | F2: 1.45 | G2: 1 | H2: 0.75 | K2: 1 | M2: =D2+E2 -> 0.8333
A3: Switchgear Insulated Case Breakers (Bus Mounted) | B3: 0.3333 | C3: 4 | D3: 0.1667 | E3: 0.1667 | F3: 0.25 | G3: 0.5 | M3: =D3+E3 -> 0.3334
A4: SwitchGear Drawout Breakers | B4: 0.3333 | C4: 4 | D4: 0.1667 | E4: 0.1 | F4: 0.25 | H4: 0.75 | M4: =D4+E4 -> 0.2667
A5: Distribution Switchboard Multi Cover (Per Section) | B5: 1.1167 | C5: 0.9333 | D5: 0.3333 | E5: 0.25 | F5: 0.8833 | G5: 0.5 | K5: 1 | M5: =D5+E5 -> 0.5833
A6: Switchboard Disconnects | B6: 0.3333 | C6: 0.2667 | D6: 0.1667 | E6: 0.1667 | F6: 0.25 | M6: =D6+E6 -> 0.3334
A7: Switchboard Molded Case Breakers | B7: 0.3333 | C7: 4 | D7: 0.1667 | E7: 0.1667 | F7: 0.25 | G7: 0.5 | M7: =D7+E7 -> 0.3334
A8: Panelboard-Single Cover > 400A (Distribution Panel) | B8: 0.9333 | C8: 0.9333 | D8: 0.3333 | E8: 0.3333 | F8: 0.8833 | G8: 0.5 | K8: 0.75 | M8: =D8+E8 -> 0.6666
A9: Panelboard-Single Cover < 400A (Branch Ckt Panel) | B9: 0.75 | C9: 0.75 | D9: 0.25 | E9: 0.1667 | F9: 0.5833 | K9: 0.5 | M9: =D9+E9 -> 0.4167
A10: Motor Control Center (MCC-Per Vertical Section) | B10: 0.4667 | C10: 0.8167 | D10: 0.1333 | E10: 0.1167 | F10: 0.4667 | K10: 0.75 | M10: =D10+E10 -> 0.25
A11: MCC: Combination Motor Starters | B11: 0.4667 | C11: 0.8167 | D11: 0.1333 | E11: 0.1167 | F11: 0.4667 | G11: 0.5 | K11: 0.75 | M11: =D11+E11 -> 0.25
A12: MCC: Molded Case Breaker | B12: 0.3333 | C12: 4 | D12: 0.1667 | E12: 0.1667 | F12: 0.25 | G12: 0.5 | M12: =D12+E12 -> 0.3334
A13: MCC: Individual Disconnect Switch | B13: 0.3333 | C13: 0.5 | D13: 0.1667 | E13: 0.1 | F13: 0.25 | M13: =D13+E13 -> 0.2667
A14: Motor Control Panel (MCP) | B14: 0.4667 | C14: 0.8167 | D14: 0.1333 | E14: 0.1167 | F14: 0.4667 | K14: 0.75 | M14: =D14+E14 -> 0.25
A15: VFD Motor Control Panel (VFD-MCP) | B15: 0.4667 | C15: 0.8167 | D15: 0.1333 | E15: 0.1167 | F15: 0.4667 | K15: 0.75 | M15: =D15+E15 -> 0.25
A16: Individual Disconnect Switch > 100A | B16: 0.3333 | C16: 0.5 | D16: 0.1667 | E16: 0.1 | F16: 0.25 | G16: 0.5 | M16: =D16+E16 -> 0.2667
A17: Individual Molded Case Breaker > 100A | B17: 0.3333 | C17: 3 | D17: 0.1667 | E17: 0.1 | F17: 0.25 | G17: 0.5 | M17: =D17+E17 -> 0.2667
A18: Individual Combination Motor Starter > 100A | B18: 0.4667 | C18: 1.33 | D18: 0.1667 | E18: 0.1167 | F18: 0.4667 | G18: 0.5 | M18: =D18+E18 -> 0.2834
A19: Oil Filled Transformer - 5kV-15kV Primary - Any Size (Pad Mounted) | B19: 0.5833 | C19: 4 | D19: 0.3333 | E19: 0.25 | F19: 0.5833 | I19: 1 | J19: 1 | L19: 0.5833 | M19: =D19+E19 -> 0.5833
A20: Oil Filled Transformer - > 15kV Primary (Substation Class) | B20: 1.3 | C20: 16 | D20: 0.75 | E20: 0.5 | F20: 1.33 | I20: 1.5 | J20: 1.5 | L20: 0.75 | M20: =D20+E20 -> 1.25
A21: Dry Type Transformer - < 480V Primary - Any Size kVA | B21: 1.0833 | C21: 1.7333 | D21: 0.417 | E21: 0.417 | F21: 1 | I21: 0.75 | J21: 0.75 | M21: =D21+E21 -> 0.834
A22: Power Factor Correction Capacitors | B22: 0.6333 | C22: 8 | D22: 0.25 | E22: 0.2 | F22: 0.5 | M22: =D22+E22 -> 0.45
A23: Lighting Contactor > 100A | B23: 0.4333 | C23: 0.75 | D23: 0.1167 | E23: 0.1 | F23: 0.1667 | M23: =D23+E23 -> 0.2167
A24: Power Distribution Unit (PDU) | B24: 1.2833 | C24: 1.25 | D24: 0.25 | E24: 0.25 | F24: 1.1167 | M24: =D24+E24 -> 0.5
A25: Wire Trough, Gutter, or Large Junction Boxes | B25: 0.3333 | C25: 0.5 | D25: 0.3333 | E25: 0.25 | F25: 0.3333 | M25: =D25+E25 -> 0.5833
A26: Bus Duct - Vertical or Horizontal (Per 10' section) | B26: 0.1167 | C26: 0.75 | D26: 0.0833 | E26: 0.0833 | F26: 0.0833 | M26: =D26+E26 -> 0.1666
A27: Automatic Transfer Switch (ATS) > 100A | B27: 0.6667 | C27: 1.5 | D27: 0.4167 | E27: 0.3333 | F27: 0.5 | M27: =D27+E27 -> 0.75
A28: Manual Transfer Switch (MTS) > 100A | B28: 0.6667 | C28: 1 | D28: 0.4167 | E28: 0.3333 | F28: 0.5 | M28: =D28+E28 -> 0.75
A29: Variable Frequency Drives (VFD) < 50 HP | B29: 0.4667 | C29: 0.8167 | D29: 0.1333 | E29: 0.1167 | F29: 0.467 | M29: =D29+E29 -> 0.25
A30: Variable Frequency Drives (VFD) 51-200 HP | B30: 0.4667 | C30: 0.8167 | D30: 0.1333 | E30: 0.1167 | F30: 0.467 | M30: =D30+E30 -> 0.25
A31: Motors < 50 HP | B31: 0.4333 | C31: 1.1167 | D31: 0.1667 | E31: 0.1 | F31: 0.4333 | M31: =D31+E31 -> 0.2667
A32: Motors 51-200 HP | B32: 0.6 | C32: 1.5 | D32: 0.1667 | E32: 0.1 | F32: 0.4333 | M32: =D32+E32 -> 0.2667
A33: Motors 201-500 HP | B33: 0.8 | C33: 1.75 | D33: 0.1667 | E33: 0.1 | F33: 0.4333 | M33: =D33+E33 -> 0.2667
... A38: Uninterruptible Power Supply (UPS) > 50kVA | B38: 0.75 | C38: 3 | D38: 0.6667 | E38: 0.6667 | F38: 0.75 | M38: =D38+E38 -> 1.3334

Sheet Components Yr 1
A1: Building | B1: Room | C1: 600 Volt and below | D1: Total Counted | E1: Basic EPM | F1: Full EPM | G1: De-Energized | H1: IR | I1: Ultrasonic | J1: A-F Collection | K1: Pri.Breaker | L1: Sec. Breaker | M1: PwrFact (partial) | N1: PwrFact (xfmr/CB) | O1: Panel Schd. | P1: Oil Sample | Q1: ESA | R1: Total Hours | S1: Total pcs. priced
A2: ='Bldgs & Rooms'!$A$2 -> Main Bldg. | B2: ='Bldgs & Rooms'!$B$2 -> 0 | C2: =Hours!$A$2 -> Switchgear - Incoming Main Service (Per Section) | D2: =MAX(E2+F2,G2,H2,I2,J2,K2,L2,M2,N2,O2,P2,Q2) -> 0 | R2: =IF(SUMPRODUCT((E2:Q2)*1)=0,0,E2*INDEX(Hours!M:M,MATCH(C2,Hours!$A:$A,0))+F2*INDEX(Hours!B:B,MATCH(C2,Hours!$A:$A,0))+G2*INDEX(Hours!C:C,MATCH(C2,Hours!$A:$A,0))+H2*INDEX(Hours!D:D,MATCH(C2,Hours!$A:$A,0))+I2*INDEX(Hours!E:E,MATCH(C2,Hours!$A:$A,0))+J2*INDEX(Hours!F:F,MATCH(C2,Hours!$A:$A,0))+K2*INDEX(Hours!G:G,MATCH(C2,Hours!$A:$A,0))+L2*INDEX(Hours!H:H,MATCH(C2,Hours!$A:$A,0))+O2*INDEX(Hours!K:K,MATCH(C2,Hours!$A:$A,0))) -> 0 | S2: =MAX(E2+F2,G2,H2,I2,J2,K2,L2,M2,N2,O2,P2,Q2) -> 0
A3: ='Bldgs & Rooms'!$A$2 -> Main Bldg. | B3: ='Bldgs & Rooms'!$B$2 -> 0 | C3: =Hours!$A$3 -> Switchgear Insulated Case Breakers (Bus Mounted) | D3: =MAX(E3+F3,G3,H3,I3,J3,K3,L3,M3,N3,O3,P3,Q3) -> 0 | R3: =IF(SUMPRODUCT((E3:Q3)*1)=0,0,E3*INDEX(Hours!M:M,MATCH(C3,Hours!$A:$A,0))+F3*INDEX(Hours!B:B,MATCH(C3,Hours!$A:$A,0))+G3*INDEX(Hours!C:C,MATCH(C3,Hours!$A:$A,0))+H3*INDEX(Hours!D:D,MATCH(C3,Hours!$A:$A,0))+I3*INDEX(Hours!E:E,MATCH(C3,Hours!$A:$A,0))+J3*INDEX(Hours!F:F,MATCH(C3,Hours!$A:$A,0))+K3*INDEX(Hours!G:G,MATCH(C3,Hours!$A:$A,0))) -> 0 | S3: =MAX(E3+F3,G3,H3,I3,J3,K3,L3,M3,N3,O3,P3,Q3) -> 0
A4: ='Bldgs & Rooms'!$A$2 -> Main Bldg. | B4: ='Bldgs & Rooms'!$B$2 -> 0 | C4: =Hours!$A$4 -> SwitchGear Drawout Breakers | D4: =MAX(E4+F4,G4,H4,I4,J4,K4,L4,M4,N4,O4,P4,Q4) -> 0 | R4: =IF(SUMPRODUCT((E4:Q4)*1)=0,0,E4*INDEX(Hours!M:M,MATCH(C4,Hours!$A:$A,0))+F4*INDEX(Hours!B:B,MATCH(C4,Hours!$A:$A,0))+G4*INDEX(Hours!C:C,MATCH(C4,Hours!$A:$A,0))+H4*INDEX(Hours!D:D,MATCH(C4,Hours!$A:$A,0))+I4*INDEX(Hours!E:E,MATCH(C4,Hours!$A:$A,0))+J4*INDEX(Hours!F:F,MATCH(C4,Hours!$A:$A,0))+L4*INDEX(Hours!H:H,MATCH(C4,Hours!$A:$A,0))) -> 0 | S4: =MAX(E4+F4,G4,H4,I4,J4,K4,L4,M4,N4,O4,P4,Q4) -> 0
A5: ='Bldgs & Rooms'!$A$2 -> Main Bldg. | B5: ='Bldgs & Rooms'!$B$2 -> 0 | C5: =Hours!$A$5 -> Distribution Switchboard Multi Cover (Per Section) | D5: =MAX(E5+F5,G5,H5,I5,J5,K5,L5,M5,N5,O5,P5,Q5) -> 0 | R5: =IF(SUMPRODUCT((E5:Q5)*1)=0,0,E5*INDEX(Hours!M:M,MATCH(C5,Hours!$A:$A,0))+F5*INDEX(Hours!B:B,MATCH(C5,Hours!$A:$A,0))+G5*INDEX(Hours!C:C,MATCH(C5,Hours!$A:$A,0))+H5*INDEX(Hours!D:D,MATCH(C5,Hours!$A:$A,0))+I5*INDEX(Hours!E:E,MATCH(C5,Hours!$A:$A,0))+J5*INDEX(Hours!F:F,MATCH(C5,Hours!$A:$A,0))+K5*INDEX(Hours!G:G,MATCH(C5,Hours!$A:$A,0))+O5*INDEX(Hours!K:K,MATCH(C5,Hours!$A:$A,0))) -> 0 | S5: =MAX(E5+F5,G5,H5,I5,J5,K5,L5,M5,N5,O5,P5,Q5) -> 0
A6: ='Bldgs & Rooms'!$A$2 -> Main Bldg. | B6: ='Bldgs & Rooms'!$B$2 -> 0 | C6: =Hours!$A$6 -> Switchboard Disconnects | D6: =MAX(E6+F6,G6,H6,I6,J6,K6,L6,M6,N6,O6,P6,Q6) -> 0 | R6: =IF(SUMPRODUCT((E6:Q6)*1)=0,0,E6*INDEX(Hours!M:M,MATCH(C6,Hours!$A:$A,0))+F6*INDEX(Hours!B:B,MATCH(C6,Hours!$A:$A,0))+G6*INDEX(Hours!C:C,MATCH(C6,Hours!$A:$A,0))+H6*INDEX(Hours!D:D,MATCH(C6,Hours!$A:$A,0))+I6*INDEX(Hours!E:E,MATCH(C6,Hours!$A:$A,0))+J6*INDEX(Hours!F:F,MATCH(C6,Hours!$A:$A,0))) -> 0 | S6: =MAX(E6+F6,G6,H6,I6,J6,K6,L6,M6,N6,O6,P6,Q6) -> 0
A7: ='Bldgs & Rooms'!$A$2 -> Main Bldg. | B7: ='Bldgs & Rooms'!$B$2 -> 0 | C7: =Hours!$A$7 -> Switchboard Molded Case Breakers | D7: =MAX(E7+F7,G7,H7,I7,J7,K7,L7,M7,N7,O7,P7,Q7) -> 0 | R7: =IF(SUMPRODUCT((E7:Q7)*1)=0,0,E7*INDEX(Hours!M:M,MATCH(C7,Hours!$A:$A,0))+F7*INDEX(Hours!B:B,MATCH(C7,Hours!$A:$A,0))+G7*INDEX(Hours!C:C,MATCH(C7,Hours!$A:$A,0))+H7*INDEX(Hours!D:D,MATCH(C7,Hours!$A:$A,0))+I7*INDEX(Hours!E:E,MATCH(C7,Hours!$A:$A,0))+J7*INDEX(Hours!F:F,MATCH(C7,Hours!$A:$A,0))+K7*INDEX(Hours!G:G,MATCH(C7,Hours!$A:$A,0))) -> 0 | S7: =MAX(E7+F7,G7,H7,I7,J7,K7,L7,M7,N7,O7,P7,Q7) -> 0
A8: ='Bldgs & Rooms'!$A$2 -> Main Bldg. | B8: ='Bldgs & Rooms'!$B$2 -> 0 | C8: =Hours!$A$8 -> Panelboard-Single Cover > 400A (Distribution Panel) | D8: =MAX(E8+F8,G8,H8,I8,J8,K8,L8,M8,N8,O8,P8,Q8) -> 0 | R8: =IF(SUMPRODUCT((E8:Q8)*1)=0,0,E8*INDEX(Hours!M:M,MATCH(C8,Hours!$A:$A,0))+F8*INDEX(Hours!B:B,MATCH(C8,Hours!$A:$A,0))+G8*INDEX(Hours!C:C,MATCH(C8,Hours!$A:$A,0))+H8*INDEX(Hours!D:D,MATCH(C8,Hours!$A:$A,0))+I8*INDEX(Hours!E:E,MATCH(C8,Hours!$A:$A,0))+J8*INDEX(Hours!F:F,MATCH(C8,Hours!$A:$A,0))+K8*INDEX(Hours!G:G,MATCH(C8,Hours!$A:$A,0))+O8*INDEX(Hours!K:K,MATCH(C8,Hours!$A:$A,0))) -> 0 | S8: =MAX(E8+F8,G8,H8,I8,J8,K8,L8,M8,N8,O8,P8,Q8) -> 0
A9: ='Bldgs & Rooms'!$A$2 -> Main Bldg. | B9: ='Bldgs & Rooms'!$B$2 -> 0 | C9: =Hours!$A$9 -> Panelboard-Single Cover < 400A (Branch Ckt Panel) | D9: =MAX(E9+F9,G9,H9,I9,J9,K9,L9,M9,N9,O9,P9,Q9) -> 0 | R9: =IF(SUMPRODUCT((E9:Q9)*1)=0,0,E9*INDEX(Hours!M:M,MATCH(C9,Hours!$A:$A,0))+F9*INDEX(Hours!B:B,MATCH(C9,Hours!$A:$A,0))+G9*INDEX(Hours!C:C,MATCH(C9,Hours!$A:$A,0))+H9*INDEX(Hours!D:D,MATCH(C9,Hours!$A:$A,0))+I9*INDEX(Hours!E:E,MATCH(C9,Hours!$A:$A,0))+J9*INDEX(Hours!F:F,MATCH(C9,Hours!$A:$A,0))+O9*INDEX(Hours!K:K,MATCH(C9,Hours!$A:$A,0))) -> 0 | S9: =MAX(E9+F9,G9,H9,I9,J9,K9,L9,M9,N9,O9,P9,Q9) -> 0
A10: ='Bldgs & Rooms'!$A$2 -> Main Bldg. | B10: ='Bldgs & Rooms'!$B$2 -> 0 | C10: =Hours!$A$10 -> Motor Control Center (MCC-Per Vertical Section) | D10: =MAX(E10+F10,G10,H10,I10,J10,K10,L10,M10,N10,O10,P10,Q10) -> 0 | R10: =IF(SUMPRODUCT((E10:Q10)*1)=0,0,E10*INDEX(Hours!M:M,MATCH(C10,Hours!$A:$A,0))+F10*INDEX(Hours!B:B,MATCH(C10,Hours!$A:$A,0))+G10*INDEX(Hours!C:C,MATCH(C10,Hours!$A:$A,0))+H10*INDEX(Hours!D:D,MATCH(C10,Hours!$A:$A,0))+I10*INDEX(Hours!E:E,MATCH(C10,Hours!$A:$A,0))+J10*INDEX(Hours!F:F,MATCH(C10,Hours!$A:$A,0))+O10*INDEX(Hours!K:K,MATCH(C10,Hours!$A:$A,0))) -> 0 | S10: =MAX(E10+F10,G10,H10,I10,J10,K10,L10,M10,N10,O10,P10,Q10) -> 0
A11: ='Bldgs & Rooms'!$A$2 -> Main Bldg. | B11: ='Bldgs & Rooms'!$B$2 -> 0 | C11: =Hours!$A$11 -> MCC: Combination Motor Starters | D11: =MAX(E11+F11,G11,H11,I11,J11,K11,L11,M11,N11,O11,P11,Q11) -> 0 | R11: =IF(SUMPRODUCT((E11:Q11)*1)=0,0,E11*INDEX(Hours!M:M,MATCH(C11,Hours!$A:$A,0))+F11*INDEX(Hours!B:B,MATCH(C11,Hours!$A:$A,0))+G11*INDEX(Hours!C:C,MATCH(C11,Hours!$A:$A,0))+H11*INDEX(Hours!D:D,MATCH(C11,Hours!$A:$A,0))+I11*INDEX(Hours!E:E,MATCH(C11,Hours!$A:$A,0))+J11*INDEX(Hours!F:F,MATCH(C11,Hours!$A:$A,0))+K11*INDEX(Hours!G:G,MATCH(C11,Hours!$A:$A,0))+O11*INDEX(Hours!K:K,MATCH(C11,Hours!$A:$A,0))) -> 0 | S11: =MAX(E11+F11,G11,H11,I11,J11,K11,L11,M11,N11,O11,P11,Q11) -> 0
A12: ='Bldgs & Rooms'!$A$2 -> Main Bldg. | B12: ='Bldgs & Rooms'!$B$2 -> 0 | C12: =Hours!$A$12 -> MCC: Molded Case Breaker | D12: =MAX(E12+F12,G12,H12,I12,J12,K12,L12,M12,N12,O12,P12,Q12) -> 0 | R12: =IF(SUMPRODUCT((E12:Q12)*1)=0,0,E12*INDEX(Hours!M:M,MATCH(C12,Hours!$A:$A,0))+F12*INDEX(Hours!B:B,MATCH(C12,Hours!$A:$A,0))+G12*INDEX(Hours!C:C,MATCH(C12,Hours!$A:$A,0))+H12*INDEX(Hours!D:D,MATCH(C12,Hours!$A:$A,0))+I12*INDEX(Hours!E:E,MATCH(C12,Hours!$A:$A,0))+J12*INDEX(Hours!F:F,MATCH(C12,Hours!$A:$A,0))+K12*INDEX(Hours!G:G,MATCH(C12,Hours!$A:$A,0))) -> 0 | S12: =MAX(E12+F12,G12,H12,I12,J12,K12,L12,M12,N12,O12,P12,Q12) -> 0
A13: ='Bldgs & Rooms'!$A$2 -> Main Bldg. | B13: ='Bldgs & Rooms'!$B$2 -> 0 | C13: =Hours!$A$13 -> MCC: Individual Disconnect Switch | D13: =MAX(E13+F13,G13,H13,I13,J13,K13,L13,M13,N13,O13,P13,Q13) -> 0 | R13: =IF(SUMPRODUCT((E13:Q13)*1)=0,0,E13*INDEX(Hours!M:M,MATCH(C13,Hours!$A:$A,0))+F13*INDEX(Hours!B:B,MATCH(C13,Hours!$A:$A,0))+G13*INDEX(Hours!C:C,MATCH(C13,Hours!$A:$A,0))+H13*INDEX(Hours!D:D,MATCH(C13,Hours!$A:$A,0))+I13*INDEX(Hours!E:E,MATCH(C13,Hours!$A:$A,0))+J13*INDEX(Hours!F:F,MATCH(C13,Hours!$A:$A,0))) -> 0 | S13: =MAX(E13+F13,G13,H13,I13,J13,K13,L13,M13,N13,O13,P13,Q13) -> 0
A14: ='Bldgs & Rooms'!$A$2 -> Main Bldg. | B14: ='Bldgs & Rooms'!$B$2 -> 0 | C14: =Hours!$A$14 -> Motor Control Panel (MCP) | D14: =MAX(E14+F14,G14,H14,I14,J14,K14,L14,M14,N14,O14,P14,Q14) -> 0 | R14: =IF(SUMPRODUCT((E14:Q14)*1)=0,0,E14*INDEX(Hours!M:M,MATCH(C14,Hours!$A:$A,0))+F14*INDEX(Hours!B:B,MATCH(C14,Hours!$A:$A,0))+G14*INDEX(Hours!C:C,MATCH(C14,Hours!$A:$A,0))+H14*INDEX(Hours!D:D,MATCH(C14,Hours!$A:$A,0))+I14*INDEX(Hours!E:E,MATCH(C14,Hours!$A:$A,0))+J14*INDEX(Hours!F:F,MATCH(C14,Hours!$A:$A,0))+O14*INDEX(Hours!K:K,MATCH(C14,Hours!$A:$A,0))) -> 0 | S14: =MAX(E14+F14,G14,H14,I14,J14,K14,L14,M14,N14,O14,P14,Q14) -> 0
A15: ='Bldgs & Rooms'!$A$2 -> Main Bldg. | B15: ='Bldgs & Rooms'!$B$2 -> 0 | C15: =Hours!$A$15 -> VFD Motor Control Panel (VFD-MCP) | D15: =MAX(E15+F15,G15,H15,I15,J15,K15,L15,M15,N15,O15,P15,Q15) -> 0 | R15: =IF(SUMPRODUCT((E15:Q15)*1)=0,0,E15*INDEX(Hours!M:M,MATCH(C15,Hours!$A:$A,0))+F15*INDEX(Hours!B:B,MATCH(C15,Hours!$A:$A,0))+G15*INDEX(Hours!C:C,MATCH(C15,Hours!$A:$A,0))+H15*INDEX(Hours!D:D,MATCH(C15,Hours!$A:$A,0))+I15*INDEX(Hours!E:E,MATCH(C15,Hours!$A:$A,0))+J15*INDEX(Hours!F:F,MATCH(C15,Hours!$A:$A,0))+O15*INDEX(Hours!K:K,MATCH(C15,Hours!$A:$A,0))) -> 0 | S15: =MAX(E15+F15,G15,H15,I15,J15,K15,L15,M15,N15,O15,P15,Q15) -> 0
A16: ='Bldgs & Rooms'!$A$2 -> Main Bldg. | B16: ='Bldgs & Rooms'!$B$2 -> 0 | C16: =Hours!$A$16 -> Individual Disconnect Switch > 100A | D16: =MAX(E16+F16,G16,H16,I16,J16,K16,L16,M16,N16,O16,P16,Q16) -> 0 | R16: =IF(SUMPRODUCT((E16:Q16)*1)=0,0,E16*INDEX(Hours!M:M,MATCH(C16,Hours!$A:$A,0))+F16*INDEX(Hours!B:B,MATCH(C16,Hours!$A:$A,0))+G16*INDEX(Hours!C:C,MATCH(C16,Hours!$A:$A,0))+H16*INDEX(Hours!D:D,MATCH(C16,Hours!$A:$A,0))+I16*INDEX(Hours!E:E,MATCH(C16,Hours!$A:$A,0))+J16*INDEX(Hours!F:F,MATCH(C16,Hours!$A:$A,0))+K16*INDEX(Hours!G:G,MATCH(C16,Hours!$A:$A,0))) -> 0 | S16: =MAX(E16+F16,G16,H16,I16,J16,K16,L16,M16,N16,O16,P16,Q16) -> 0
A17: ='Bldgs & Rooms'!$A$2 -> Main Bldg. | B17: ='Bldgs & Rooms'!$B$2 -> 0 | C17: =Hours!$A$17 -> Individual Molded Case Breaker > 100A | D17: =MAX(E17+F17,G17,H17,I17,J17,K17,L17,M17,N17,O17,P17,Q17) -> 0 | R17: =IF(SUMPRODUCT((E17:Q17)*1)=0,0,E17*INDEX(Hours!M:M,MATCH(C17,Hours!$A:$A,0))+F17*INDEX(Hours!B:B,MATCH(C17,Hours!$A:$A,0))+G17*INDEX(Hours!C:C,MATCH(C17,Hours!$A:$A,0))+H17*INDEX(Hours!D:D,MATCH(C17,Hours!$A:$A,0))+I17*INDEX(Hours!E:E,MATCH(C17,Hours!$A:$A,0))+J17*INDEX(Hours!F:F,MATCH(C17,Hours!$A:$A,0))+K17*INDEX(Hours!G:G,MATCH(C17,Hours!$A:$A,0))) -> 0 | S17: =MAX(E17+F17,G17,H17,I17,J17,K17,L17,M17,N17,O17,P17,Q17) -> 0
A18: ='Bldgs & Rooms'!$A$2 -> Main Bldg. | B18: ='Bldgs & Rooms'!$B$2 -> 0 | C18: =Hours!$A$18 -> Individual Combination Motor Starter > 100A | D18: =MAX(E18+F18,G18,H18,I18,J18,K18,L18,M18,N18,O18,P18,Q18) -> 0 | R18: =IF(SUMPRODUCT((E18:Q18)*1)=0,0,E18*INDEX(Hours!M:M,MATCH(C18,Hours!$A:$A,0))+F18*INDEX(Hours!B:B,MATCH(C18,Hours!$A:$A,0))+G18*INDEX(Hours!C:C,MATCH(C18,Hours!$A:$A,0))+H18*INDEX(Hours!D:D,MATCH(C18,Hours!$A:$A,0))+I18*INDEX(Hours!E:E,MATCH(C18,Hours!$A:$A,0))+J18*INDEX(Hours!F:F,MATCH(C18,Hours!$A:$A,0))+K18*INDEX(Hours!G:G,MATCH(C18,Hours!$A:$A,0))) -> 0 | S18: =MAX(E18+F18,G18,H18,I18,J18,K18,L18,M18,N18,O18,P18,Q18) -> 0
A19: ='Bldgs & Rooms'!$A$2 -> Main Bldg. | B19: ='Bldgs & Rooms'!$B$2 -> 0 | C19: =Hours!$A$19 -> Oil Filled Transformer - 5kV-15kV Primary - Any Size (Pad Mounted) | D19: =MAX(E19+F19,G19,H19,I19,J19,K19,L19,M19,N19,O19,P19,Q19) -> 0 | R19: =IF(SUMPRODUCT((E19:Q19)*1)=0,0,E19*INDEX(Hours!M:M,MATCH(C19,Hours!$A:$A,0))+F19*INDEX(Hours!B:B,MATCH(C19,Hours!$A:$A,0))+G19*INDEX(Hours!C:C,MATCH(C19,Hours!$A:$A,0))+H19*INDEX(Hours!D:D,MATCH(C19,Hours!$A:$A,0))+I19*INDEX(Hours!E:E,MATCH(C19,Hours!$A:$A,0))+J19*INDEX(Hours!F:F,MATCH(C19,Hours!$A:$A,0))+M19*INDEX(Hours!I:I,MATCH(C19,Hours!$A:$A,0))+N19*INDEX(Hours!J:J,MATCH(C19,Hours!$A:$A,0))+P19*INDEX(Hours!L:L,MATCH(C19,Hours!$A:$A,0))) -> 0 | S19: =MAX(E19+F19,G19,H19,I19,J19,K19,L19,M19,N19,O19,P19,Q19) -> 0
A20: ='Bldgs & Rooms'!$A$2 -> Main Bldg. | B20: ='Bldgs & Rooms'!$B$2 -> 0 | C20: =Hours!$A$20 -> Oil Filled Transformer - > 15kV Primary (Substation Class) | D20: =MAX(E20+F20,G20,H20,I20,J20,K20,L20,M20,N20,O20,P20,Q20) -> 0 | R20: =IF(SUMPRODUCT((E20:Q20)*1)=0,0,E20*INDEX(Hours!M:M,MATCH(C20,Hours!$A:$A,0))+F20*INDEX(Hours!B:B,MATCH(C20,Hours!$A:$A,0))+G20*INDEX(Hours!C:C,MATCH(C20,Hours!$A:$A,0))+H20*INDEX(Hours!D:D,MATCH(C20,Hours!$A:$A,0))+I20*INDEX(Hours!E:E,MATCH(C20,Hours!$A:$A,0))+J20*INDEX(Hours!F:F,MATCH(C20,Hours!$A:$A,0))+M20*INDEX(Hours!I:I,MATCH(C20,Hours!$A:$A,0))+N20*INDEX(Hours!J:J,MATCH(C20,Hours!$A:$A,0))+P20*INDEX(Hours!L:L,MATCH(C20,Hours!$A:$A,0))) -> 0 | S20: =MAX(E20+F20,G20,H20,I20,J20,K20,L20,M20,N20,O20,P20,Q20) -> 0
A21: ='Bldgs & Rooms'!$A$2 -> Main Bldg. | B21: ='Bldgs & Rooms'!$B$2 -> 0 | C21: =Hours!$A$21 -> Dry Type Transformer - < 480V Primary - Any Size kVA | D21: =MAX(E21+F21,G21,H21,I21,J21,K21,L21,M21,N21,O21,P21,Q21) -> 0 | R21: =IF(SUMPRODUCT((E21:Q21)*1)=0,0,E21*INDEX(Hours!M:M,MATCH(C21,Hours!$A:$A,0))+F21*INDEX(Hours!B:B,MATCH(C21,Hours!$A:$A,0))+G21*INDEX(Hours!C:C,MATCH(C21,Hours!$A:$A,0))+H21*INDEX(Hours!D:D,MATCH(C21,Hours!$A:$A,0))+I21*INDEX(Hours!E:E,MATCH(C21,Hours!$A:$A,0))+J21*INDEX(Hours!F:F,MATCH(C21,Hours!$A:$A,0))+M21*INDEX(Hours!I:I,MATCH(C21,Hours!$A:$A,0))+N21*INDEX(Hours!J:J,MATCH(C21,Hours!$A:$A,0))) -> 0 | S21: =MAX(E21+F21,G21,H21,I21,J21,K21,L21,M21,N21,O21,P21,Q21) -> 0
A22: ='Bldgs & Rooms'!$A$2 -> Main Bldg. | B22: ='Bldgs & Rooms'!$B$2 -> 0 | C22: =Hours!$A$22 -> Power Factor Correction Capacitors | D22: =MAX(E22+F22,G22,H22,I22,J22,K22,L22,M22,N22,O22,P22,Q22) -> 0 | R22: =IF(SUMPRODUCT((E22:Q22)*1)=0,0,E22*INDEX(Hours!M:M,MATCH(C22,Hours!$A:$A,0))+F22*INDEX(Hours!B:B,MATCH(C22,Hours!$A:$A,0))+G22*INDEX(Hours!C:C,MATCH(C22,Hours!$A:$A,0))+H22*INDEX(Hours!D:D,MATCH(C22,Hours!$A:$A,0))+I22*INDEX(Hours!E:E,MATCH(C22,Hours!$A:$A,0))+J22*INDEX(Hours!F:F,MATCH(C22,Hours!$A:$A,0))) -> 0 | S22: =MAX(E22+F22,G22,H22,I22,J22,K22,L22,M22,N22,O22,P22,Q22) -> 0
A23: ='Bldgs & Rooms'!$A$2 -> Main Bldg. | B23: ='Bldgs & Rooms'!$B$2 -> 0 | C23: =Hours!$A$23 -> Lighting Contactor > 100A | D23: =MAX(E23+F23,G23,H23,I23,J23,K23,L23,M23,N23,O23,P23,Q23) -> 0 | R23: =IF(SUMPRODUCT((E23:Q23)*1)=0,0,E23*INDEX(Hours!M:M,MATCH(C23,Hours!$A:$A,0))+F23*INDEX(Hours!B:B,MATCH(C23,Hours!$A:$A,0))+G23*INDEX(Hours!C:C,MATCH(C23,Hours!$A:$A,0))+H23*INDEX(Hours!D:D,MATCH(C23,Hours!$A:$A,0))+I23*INDEX(Hours!E:E,MATCH(C23,Hours!$A:$A,0))+J23*INDEX(Hours!F:F,MATCH(C23,Hours!$A:$A,0))) -> 0 | S23: =MAX(E23+F23,G23,H23,I23,J23,K23,L23,M23,N23,O23,P23,Q23) -> 0
A24: ='Bldgs & Rooms'!$A$2 -> Main Bldg. | B24: ='Bldgs & Rooms'!$B$2 -> 0 | C24: =Hours!$A$24 -> Power Distribution Unit (PDU) | D24: =MAX(E24+F24,G24,H24,I24,J24,K24,L24,M24,N24,O24,P24,Q24) -> 0 | R24: =IF(SUMPRODUCT((E24:Q24)*1)=0,0,E24*INDEX(Hours!M:M,MATCH(C24,Hours!$A:$A,0))+F24*INDEX(Hours!B:B,MATCH(C24,Hours!$A:$A,0))+G24*INDEX(Hours!C:C,MATCH(C24,Hours!$A:$A,0))+H24*INDEX(Hours!D:D,MATCH(C24,Hours!$A:$A,0))+I24*INDEX(Hours!E:E,MATCH(C24,Hours!$A:$A,0))+J24*INDEX(Hours!F:F,MATCH(C24,Hours!$A:$A,0))) -> 0 | S24: =MAX(E24+F24,G24,H24,I24,J24,K24,L24,M24,N24,O24,P24,Q24) -> 0
A25: ='Bldgs & Rooms'!$A$2 -> Main Bldg. | B25: ='Bldgs & Rooms'!$B$2 -> 0 | C25: =Hours!$A$25 -> Wire Trough, Gutter, or Large Junction Boxes | D25: =MAX(E25+F25,G25,H25,I25,J25,K25,L25,M25,N25,O25,P25,Q25) -> 0 | R25: =IF(SUMPRODUCT((E25:Q25)*1)=0,0,E25*INDEX(Hours!M:M,MATCH(C25,Hours!$A:$A,0))+F25*INDEX(Hours!B:B,MATCH(C25,Hours!$A:$A,0))+G25*INDEX(Hours!C:C,MATCH(C25,Hours!$A:$A,0))+H25*INDEX(Hours!D:D,MATCH(C25,Hours!$A:$A,0))+I25*INDEX(Hours!E:E,MATCH(C25,Hours!$A:$A,0))+J25*INDEX(Hours!F:F,MATCH(C25,Hours!$A:$A,0))) -> 0 | S25: =MAX(E25+F25,G25,H25,I25,J25,K25,L25,M25,N25,O25,P25,Q25) -> 0
A26: ='Bldgs & Rooms'!$A$2 -> Main Bldg. | B26: ='Bldgs & Rooms'!$B$2 -> 0 | C26: =Hours!$A$26 -> Bus Duct - Vertical or Horizontal (Per 10' section) | D26: =MAX(E26+F26,G26,H26,I26,J26,K26,L26,M26,N26,O26,P26,Q26) -> 0 | R26: =IF(SUMPRODUCT((E26:Q26)*1)=0,0,E26*INDEX(Hours!M:M,MATCH(C26,Hours!$A:$A,0))+F26*INDEX(Hours!B:B,MATCH(C26,Hours!$A:$A,0))+G26*INDEX(Hours!C:C,MATCH(C26,Hours!$A:$A,0))+H26*INDEX(Hours!D:D,MATCH(C26,Hours!$A:$A,0))+I26*INDEX(Hours!E:E,MATCH(C26,Hours!$A:$A,0))+J26*INDEX(Hours!F:F,MATCH(C26,Hours!$A:$A,0))) -> 0 | S26: =MAX(E26+F26,G26,H26,I26,J26,K26,L26,M26,N26,O26,P26,Q26) -> 0
A27: ='Bldgs & Rooms'!$A$2 -> Main Bldg. | B27: ='Bldgs & Rooms'!$B$2 -> 0 | C27: =Hours!$A$27 -> Automatic Transfer Switch (ATS) > 100A | D27: =MAX(E27+F27,G27,H27,I27,J27,K27,L27,M27,N27,O27,P27,Q27) -> 0 | R27: =IF(SUMPRODUCT((E27:Q27)*1)=0,0,E27*INDEX(Hours!M:M,MATCH(C27,Hours!$A:$A,0))+F27*INDEX(Hours!B:B,MATCH(C27,Hours!$A:$A,0))+G27*INDEX(Hours!C:C,MATCH(C27,Hours!$A:$A,0))+H27*INDEX(Hours!D:D,MATCH(C27,Hours!$A:$A,0))+I27*INDEX(Hours!E:E,MATCH(C27,Hours!$A:$A,0))+J27*INDEX(Hours!F:F,MATCH(C27,Hours!$A:$A,0))) -> 0 | S27: =MAX(E27+F27,G27,H27,I27,J27,K27,L27,M27,N27,O27,P27,Q27) -> 0
A28: ='Bldgs & Rooms'!$A$2 -> Main Bldg. | B28: ='Bldgs & Rooms'!$B$2 -> 0 | C28: =Hours!$A$28 -> Manual Transfer Switch (MTS) > 100A | D28: =MAX(E28+F28,G28,H28,I28,J28,K28,L28,M28,N28,O28,P28,Q28) -> 0 | R28: =IF(SUMPRODUCT((E28:Q28)*1)=0,0,E28*INDEX(Hours!M:M,MATCH(C28,Hours!$A:$A,0))+F28*INDEX(Hours!B:B,MATCH(C28,Hours!$A:$A,0))+G28*INDEX(Hours!C:C,MATCH(C28,Hours!$A:$A,0))+H28*INDEX(Hours!D:D,MATCH(C28,Hours!$A:$A,0))+I28*INDEX(Hours!E:E,MATCH(C28,Hours!$A:$A,0))+J28*INDEX(Hours!F:F,MATCH(C28,Hours!$A:$A,0))) -> 0 | S28: =MAX(E28+F28,G28,H28,I28,J28,K28,L28,M28,N28,O28,P28,Q28) -> 0
A29: ='Bldgs & Rooms'!$A$2 -> Main Bldg. | B29: ='Bldgs & Rooms'!$B$2 -> 0 | C29: =Hours!$A$29 -> Variable Frequency Drives (VFD) < 50 HP | D29: =MAX(E29+F29,G29,H29,I29,J29,K29,L29,M29,N29,O29,P29,Q29) -> 0 | R29: =IF(SUMPRODUCT((E29:Q29)*1)=0,0,E29*INDEX(Hours!M:M,MATCH(C29,Hours!$A:$A,0))+F29*INDEX(Hours!B:B,MATCH(C29,Hours!$A:$A,0))+G29*INDEX(Hours!C:C,MATCH(C29,Hours!$A:$A,0))+H29*INDEX(Hours!D:D,MATCH(C29,Hours!$A:$A,0))+I29*INDEX(Hours!E:E,MATCH(C29,Hours!$A:$A,0))+J29*INDEX(Hours!F:F,MATCH(C29,Hours!$A:$A,0))) -> 0 | S29: =MAX(E29+F29,G29,H29,I29,J29,K29,L29,M29,N29,O29,P29,Q29) -> 0
A30: ='Bldgs & Rooms'!$A$2 -> Main Bldg. | B30: ='Bldgs & Rooms'!$B$2 -> 0 | C30: =Hours!$A$30 -> Variable Frequency Drives (VFD) 51-200 HP | D30: =MAX(E30+F30,G30,H30,I30,J30,K30,L30,M30,N30,O30,P30,Q30) -> 0 | R30: =IF(SUMPRODUCT((E30:Q30)*1)=0,0,E30*INDEX(Hours!M:M,MATCH(C30,Hours!$A:$A,0))+F30*INDEX(Hours!B:B,MATCH(C30,Hours!$A:$A,0))+G30*INDEX(Hours!C:C,MATCH(C30,Hours!$A:$A,0))+H30*INDEX(Hours!D:D,MATCH(C30,Hours!$A:$A,0))+I30*INDEX(Hours!E:E,MATCH(C30,Hours!$A:$A,0))+J30*INDEX(Hours!F:F,MATCH(C30,Hours!$A:$A,0))) -> 0 | S30: =MAX(E30+F30,G30,H30,I30,J30,K30,L30,M30,N30,O30,P30,Q30) -> 0
A31: ='Bldgs & Rooms'!$A$2 -> Main Bldg. | B31: ='Bldgs & Rooms'!$B$2 -> 0 | C31: =Hours!$A$31 -> Motors < 50 HP | D31: =MAX(E31+F31,G31,H31,I31,J31,K31,L31,M31,N31,O31,P31,Q31) -> 0 | R31: =IF(SUMPRODUCT((E31:Q31)*1)=0,0,E31*INDEX(Hours!M:M,MATCH(C31,Hours!$A:$A,0))+F31*INDEX(Hours!B:B,MATCH(C31,Hours!$A:$A,0))+G31*INDEX(Hours!C:C,MATCH(C31,Hours!$A:$A,0))+H31*INDEX(Hours!D:D,MATCH(C31,Hours!$A:$A,0))+I31*INDEX(Hours!E:E,MATCH(C31,Hours!$A:$A,0))+J31*INDEX(Hours!F:F,MATCH(C31,Hours!$A:$A,0))) -> 0 | S31: =MAX(E31+F31,G31,H31,I31,J31,K31,L31,M31,N31,O31,P31,Q31) -> 0
A32: ='Bldgs & Rooms'!$A$2 -> Main Bldg. | B32: ='Bldgs & Rooms'!$B$2 -> 0 | C32: =Hours!$A$32 -> Motors 51-200 HP | D32: =MAX(E32+F32,G32,H32,I32,J32,K32,L32,M32,N32,O32,P32,Q32) -> 0 | R32: =IF(SUMPRODUCT((E32:Q32)*1)=0,0,E32*INDEX(Hours!M:M,MATCH(C32,Hours!$A:$A,0))+F32*INDEX(Hours!B:B,MATCH(C32,Hours!$A:$A,0))+G32*INDEX(Hours!C:C,MATCH(C32,Hours!$A:$A,0))+H32*INDEX(Hours!D:D,MATCH(C32,Hours!$A:$A,0))+I32*INDEX(Hours!E:E,MATCH(C32,Hours!$A:$A,0))+J32*INDEX(Hours!F:F,MATCH(C32,Hours!$A:$A,0))) -> 0 | S32: =MAX(E32+F32,G32,H32,I32,J32,K32,L32,M32,N32,O32,P32,Q32) -> 0
A33: ='Bldgs & Rooms'!$A$2 -> Main Bldg. | B33: ='Bldgs & Rooms'!$B$2 -> 0 | C33: =Hours!$A$33 -> Motors 201-500 HP | D33: =MAX(E33+F33,G33,H33,I33,J33,K33,L33,M33,N33,O33,P33,Q33) -> 0 | R33: =IF(SUMPRODUCT((E33:Q33)*1)=0,0,E33*INDEX(Hours!M:M,MATCH(C33,Hours!$A:$A,0))+F33*INDEX(Hours!B:B,MATCH(C33,Hours!$A:$A,0))+G33*INDEX(Hours!C:C,MATCH(C33,Hours!$A:$A,0))+H33*INDEX(Hours!D:D,MATCH(C33,Hours!$A:$A,0))+I33*INDEX(Hours!E:E,MATCH(C33,Hours!$A:$A,0))+J33*INDEX(Hours!F:F,MATCH(C33,Hours!$A:$A,0))) -> 0 | S33: =MAX(E33+F33,G33,H33,I33,J33,K33,L33,M33,N33,O33,P33,Q33) -> 0
A34: ='Bldgs & Rooms'!$A$2 -> Main Bldg. | B34: ='Bldgs & Rooms'!$B$2 -> 0 | C34: =Hours!$A$34 -> Compressed Air Equipment | D34: =MAX(E34+F34,G34,H34,I34,J34,K34,L34,M34,N34,O34,P34,Q34) -> 0 | R34: =IF(SUMPRODUCT((E34:Q34)*1)=0,0,E34*INDEX(Hours!M:M,MATCH(C34,Hours!$A:$A,0))+F34*INDEX(Hours!B:B,MATCH(C34,Hours!$A:$A,0))+G34*INDEX(Hours!C:C,MATCH(C34,Hours!$A:$A,0))+H34*INDEX(Hours!D:D,MATCH(C34,Hours!$A:$A,0))+I34*INDEX(Hours!E:E,MATCH(C34,Hours!$A:$A,0))+J34*INDEX(Hours!F:F,MATCH(C34,Hours!$A:$A,0))) -> 0 | S34: =MAX(E34+F34,G34,H34,I34,J34,K34,L34,M34,N34,O34,P34,Q34) -> 0
A35: ='Bldgs & Rooms'!$A$2 -> Main Bldg. | B35: ='Bldgs & Rooms'!$B$2 -> 0 | C35: =Hours!$A$35 -> HVAC Equipment (Large) | D35: =MAX(E35+F35,G35,H35,I35,J35,K35,L35,M35,N35,O35,P35,Q35) -> 0 | R35: =IF(SUMPRODUCT((E35:Q35)*1)=0,0,E35*INDEX(Hours!M:M,MATCH(C35,Hours!$A:$A,0))+F35*INDEX(Hours!B:B,MATCH(C35,Hours!$A:$A,0))+G35*INDEX(Hours!C:C,MATCH(C35,Hours!$A:$A,0))+H35*INDEX(Hours!D:D,MATCH(C35,Hours!$A:$A,0))+I35*INDEX(Hours!E:E,MATCH(C35,Hours!$A:$A,0))+J35*INDEX(Hours!F:F,MATCH(C35,Hours!$A:$A,0))) -> 0 | S35: =MAX(E35+F35,G35,H35,I35,J35,K35,L35,M35,N35,O35,P35,Q35) -> 0
A36: ='Bldgs & Rooms'!$A$2 -> Main Bldg. | B36: ='Bldgs & Rooms'!$B$2 -> 0 | C36: =Hours!$A$36 -> HVAC Equipment (Small) | D36: =MAX(E36+F36,G36,H36,I36,J36,K36,L36,M36,N36,O36,P36,Q36) -> 0 | R36: =IF(SUMPRODUCT((E36:Q36)*1)=0,0,E36*INDEX(Hours!M:M,MATCH(C36,Hours!$A:$A,0))+F36*INDEX(Hours!B:B,MATCH(C36,Hours!$A:$A,0))+G36*INDEX(Hours!C:C,MATCH(C36,Hours!$A:$A,0))+H36*INDEX(Hours!D:D,MATCH(C36,Hours!$A:$A,0))+I36*INDEX(Hours!E:E,MATCH(C36,Hours!$A:$A,0))+J36*INDEX(Hours!F:F,MATCH(C36,Hours!$A:$A,0))) -> 0 | S36: =MAX(E36+F36,G36,H36,I36,J36,K36,L36,M36,N36,O36,P36,Q36) -> 0
A37: ='Bldgs & Rooms'!$A$2 -> Main Bldg. | B37: ='Bldgs & Rooms'!$B$2 -> 0 | C37: =Hours!$A$37 -> Uninterruptible Power Supply (UPS) < 50kVA | D37: =MAX(E37+F37,G37,H37,I37,J37,K37,L37,M37,N37,O37,P37,Q37) -> 0 | R37: =IF(SUMPRODUCT((E37:Q37)*1)=0,0,E37*INDEX(Hours!M:M,MATCH(C37,Hours!$A:$A,0))+F37*INDEX(Hours!B:B,MATCH(C37,Hours!$A:$A,0))+G37*INDEX(Hours!C:C,MATCH(C37,Hours!$A:$A,0))+H37*INDEX(Hours!D:D,MATCH(C37,Hours!$A:$A,0))+I37*INDEX(Hours!E:E,MATCH(C37,Hours!$A:$A,0))+J37*INDEX(Hours!F:F,MATCH(C37,Hours!$A:$A,0))) -> 0 | S37: =MAX(E37+F37,G37,H37,I37,J37,K37,L37,M37,N37,O37,P37,Q37) -> 0
A38: ='Bldgs & Rooms'!$A$2 -> Main Bldg. | B38: ='Bldgs & Rooms'!$B$2 -> 0 | C38: =Hours!$A$38 -> Uninterruptible Power Supply (UPS) > 50kVA | D38: =MAX(E38+F38,G38,H38,I38,J38,K38,L38,M38,N38,O38,P38,Q38) -> 0 | R38: =IF(SUMPRODUCT((E38:Q38)*1)=0,0,E38*INDEX(Hours!M:M,MATCH(C38,Hours!$A:$A,0))+F38*INDEX(Hours!B:B,MATCH(C38,Hours!$A:$A,0))+G38*INDEX(Hours!C:C,MATCH(C38,Hours!$A:$A,0))+H38*INDEX(Hours!D:D,MATCH(C38,Hours!$A:$A,0))+I38*INDEX(Hours!E:E,MATCH(C38,Hours!$A:$A,0))+J38*INDEX(Hours!F:F,MATCH(C38,Hours!$A:$A,0))) -> 0 | S38: =MAX(E38+F38,G38,H38,I38,J38,K38,L38,M38,N38,O38,P38,Q38) -> 0
A39: ='Bldgs & Rooms'!$A$3 -> Main Bldg. | B39: ='Bldgs & Rooms'!$B$3 -> 0 | C39: =Hours!$A$2 -> Switchgear - Incoming Main Service (Per Section) | D39: =MAX(E39+F39,G39,H39,I39,J39,K39,L39,M39,N39,O39,P39,Q39) -> 0 | R39: =IF(SUMPRODUCT((E39:Q39)*1)=0,0,E39*INDEX(Hours!M:M,MATCH(C39,Hours!$A:$A,0))+F39*INDEX(Hours!B:B,MATCH(C39,Hours!$A:$A,0))+G39*INDEX(Hours!C:C,MATCH(C39,Hours!$A:$A,0))+H39*INDEX(Hours!D:D,MATCH(C39,Hours!$A:$A,0))+I39*INDEX(Hours!E:E,MATCH(C39,Hours!$A:$A,0))+J39*INDEX(Hours!F:F,MATCH(C39,Hours!$A:$A,0))+K39*INDEX(Hours!G:G,MATCH(C39,Hours!$A:$A,0))+L39*INDEX(Hours!H:H,MATCH(C39,Hours!$A:$A,0))+O39*INDEX(Hours!K:K,MATCH(C39,Hours!$A:$A,0))) -> 0 | S39: =MAX(E39+F39,G39,H39,I39,J39,K39,L39,M39,N39,O39,P39,Q39) -> 0
A40: ='Bldgs & Rooms'!$A$3 -> Main Bldg. | B40: ='Bldgs & Rooms'!$B$3 -> 0 | C40: =Hours!$A$3 -> Switchgear Insulated Case Breakers (Bus Mounted) | D40: =MAX(E40+F40,G40,H40,I40,J40,K40,L40,M40,N40,O40,P40,Q40) -> 0 | R40: =IF(SUMPRODUCT((E40:Q40)*1)=0,0,E40*INDEX(Hours!M:M,MATCH(C40,Hours!$A:$A,0))+F40*INDEX(Hours!B:B,MATCH(C40,Hours!$A:$A,0))+G40*INDEX(Hours!C:C,MATCH(C40,Hours!$A:$A,0))+H40*INDEX(Hours!D:D,MATCH(C40,Hours!$A:$A,0))+I40*INDEX(Hours!E:E,MATCH(C40,Hours!$A:$A,0))+J40*INDEX(Hours!F:F,MATCH(C40,Hours!$A:$A,0))+K40*INDEX(Hours!G:G,MATCH(C40,Hours!$A:$A,0))) -> 0 | S40: =MAX(E40+F40,G40,H40,I40,J40,K40,L40,M40,N40,O40,P40,Q40) -> 0
...

Sheet Components Yr 2
A1: Building | B1: Room | C1: 600 Volt and below | D1: Total Counted | E1: Basic EPM | F1: Full EPM | G1: De-Energized | H1: IR | I1: Ultrasonic | J1: A-F Collection | K1: Pri.Breaker | L1: Sec. Breaker | M1: PwrFact (partial) | N1: PwrFact (xfmr/CB) | O1: Panel Schd. | P1: Oil Sample | Q1: ESA | R1: Total Hours | S1: Total pcs. priced
A2: ='Bldgs & Rooms'!$A$2 -> Main Bldg. | B2: ='Bldgs & Rooms'!$B$2 -> 0 | C2: =Hours!$A$2 -> Switchgear - Incoming Main Service (Per Section) | D2: =MAX(E2+F2,G2,H2,I2,J2,K2,L2,M2,N2,O2,P2,Q2) -> 0 | E2: =IF('Components Yr 1'!E2=0,0,'Components Yr 1'!E2) -> 0 | F2: =IF('Components Yr 1'!F2=0,0,'Components Yr 1'!F2) -> 0 | G2: =IF('Components Yr 1'!G2=0,0,'Components Yr 1'!G2) -> 0 | H2: =IF('Components Yr 1'!H2=0,0,'Components Yr 1'!H2) -> 0 | I2: =IF('Components Yr 1'!I2=0,0,'Components Yr 1'!I2) -> 0 | J2: =IF('Components Yr 1'!J2=0,0,'Components Yr 1'!J2) -> 0 | K2: =IF('Components Yr 1'!K2=0,0,'Components Yr 1'!K2) -> 0 | L2: =IF('Components Yr 1'!L2=0,0,'Components Yr 1'!L2) -> 0 | O2: =IF('Components Yr 1'!O2=0,0,'Components Yr 1'!O2) -> 0 | R2: =IF(SUMPRODUCT((E2:Q2)*1)=0,0,E2*INDEX(Hours!M:M,MATCH(C2,Hours!$A:$A,0))+F2*INDEX(Hours!B:B,MATCH(C2,Hours!$A:$A,0))+G2*INDEX(Hours!C:C,MATCH(C2,Hours!$A:$A,0))+H2*INDEX(Hours!D:D,MATCH(C2,Hours!$A:$A,0))+I2*INDEX(Hours!E:E,MATCH(C2,Hours!$A:$A,0))+J2*INDEX(Hours!F:F,MATCH(C2,Hours!$A:$A,0))+K2*INDEX(Hours!G:G,MATCH(C2,Hours!$A:$A,0))+L2*INDEX(Hours!H:H,MATCH(C2,Hours!$A:$A,0))+O2*INDEX(Hours!K:K,MATCH(C2,Hours!$A:$A,0))) -> 0 | S2: =MAX(E2+F2,G2,H2,I2,J2,K2,L2,M2,N2,O2,P2,Q2) -> 0
A3: ='Bldgs & Rooms'!$A$2 -> Main Bldg. | B3: ='Bldgs & Rooms'!$B$2 -> 0 | C3: =Hours!$A$3 -> Switchgear Insulated Case Breakers (Bus Mounted) | D3: =MAX(E3+F3,G3,H3,I3,J3,K3,L3,M3,N3,O3,P3,Q3) -> 0 | E3: =IF('Components Yr 1'!E3=0,0,'Components Yr 1'!E3) -> 0 | F3: =IF('Components Yr 1'!F3=0,0,'Components Yr 1'!F3) -> 0 | G3: =IF('Components Yr 1'!G3=0,0,'Components Yr 1'!G3) -> 0 | H3: =IF('Components Yr 1'!H3=0,0,'Components Yr 1'!H3) -> 0 | I3: =IF('Components Yr 1'!I3=0,0,'Components Yr 1'!I3) -> 0 | J3: =IF('Components Yr 1'!J3=0,0,'Components Yr 1'!J3) -> 0 | K3: =IF('Components Yr 1'!K3=0,0,'Components Yr 1'!K3) -> 0 | R3: =IF(SUMPRODUCT((E3:Q3)*1)=0,0,E3*INDEX(Hours!M:M,MATCH(C3,Hours!$A:$A,0))+F3*INDEX(Hours!B:B,MATCH(C3,Hours!$A:$A,0))+G3*INDEX(Hours!C:C,MATCH(C3,Hours!$A:$A,0))+H3*INDEX(Hours!D:D,MATCH(C3,Hours!$A:$A,0))+I3*INDEX(Hours!E:E,MATCH(C3,Hours!$A:$A,0))+J3*INDEX(Hours!F:F,MATCH(C3,Hours!$A:$A,0))+K3*INDEX(Hours!G:G,MATCH(C3,Hours!$A:$A,0))) -> 0 | S3: =MAX(E3+F3,G3,H3,I3,J3,K3,L3,M3,N3,O3,P3,Q3) -> 0
A4: ='Bldgs & Rooms'!$A$2 -> Main Bldg. | B4: ='Bldgs & Rooms'!$B$2 -> 0 | C4: =Hours!$A$4 -> SwitchGear Drawout Breakers | D4: =MAX(E4+F4,G4,H4,I4,J4,K4,L4,M4,N4,O4,P4,Q4) -> 0 | E4: =IF('Components Yr 1'!E4=0,0,'Components Yr 1'!E4) -> 0 | F4: =IF('Components Yr 1'!F4=0,0,'Components Yr 1'!F4) -> 0 | G4: =IF('Components Yr 1'!G4=0,0,'Components Yr 1'!G4) -> 0 | H4: =IF('Components Yr 1'!H4=0,0,'Components Yr 1'!H4) -> 0 | I4: =IF('Components Yr 1'!I4=0,0,'Components Yr 1'!I4) -> 0 | J4: =IF('Components Yr 1'!J4=0,0,'Components Yr 1'!J4) -> 0 | L4: =IF('Components Yr 1'!L4=0,0,'Components Yr 1'!L4) -> 0 | R4: =IF(SUMPRODUCT((E4:Q4)*1)=0,0,E4*INDEX(Hours!M:M,MATCH(C4,Hours!$A:$A,0))+F4*INDEX(Hours!B:B,MATCH(C4,Hours!$A:$A,0))+G4*INDEX(Hours!C:C,MATCH(C4,Hours!$A:$A,0))+H4*INDEX(Hours!D:D,MATCH(C4,Hours!$A:$A,0))+I4*INDEX(Hours!E:E,MATCH(C4,Hours!$A:$A,0))+J4*INDEX(Hours!F:F,MATCH(C4,Hours!$A:$A,0))+L4*INDEX(Hours!H:H,MATCH(C4,Hours!$A:$A,0))) -> 0 | S4: =MAX(E4+F4,G4,H4,I4,J4,K4,L4,M4,N4,O4,P4,Q4) -> 0
A5: ='Bldgs & Rooms'!$A$2 -> Main Bldg. | B5: ='Bldgs & Rooms'!$B$2 -> 0 | C5: =Hours!$A$5 -> Distribution Switchboard Multi Cover (Per Section) | D5: =MAX(E5+F5,G5,H5,I5,J5,K5,L5,M5,N5,O5,P5,Q5) -> 0 | E5: =IF('Components Yr 1'!E5=0,0,'Components Yr 1'!E5) -> 0 | F5: =IF('Components Yr 1'!F5=0,0,'Components Yr 1'!F5) -> 0 | G5: =IF('Components Yr 1'!G5=0,0,'Components Yr 1'!G5) -> 0 | H5: =IF('Components Yr 1'!H5=0,0,'Components Yr 1'!H5) -> 0 | I5: =IF('Components Yr 1'!I5=0,0,'Components Yr 1'!I5) -> 0 | J5: =IF('Components Yr 1'!J5=0,0,'Components Yr 1'!J5) -> 0 | K5: =IF('Components Yr 1'!K5=0,0,'Components Yr 1'!K5) -> 0 | O5: =IF('Components Yr 1'!O5=0,0,'Components Yr 1'!O5) -> 0 | R5: =IF(SUMPRODUCT((E5:Q5)*1)=0,0,E5*INDEX(Hours!M:M,MATCH(C5,Hours!$A:$A,0))+F5*INDEX(Hours!B:B,MATCH(C5,Hours!$A:$A,0))+G5*INDEX(Hours!C:C,MATCH(C5,Hours!$A:$A,0))+H5*INDEX(Hours!D:D,MATCH(C5,Hours!$A:$A,0))+I5*INDEX(Hours!E:E,MATCH(C5,Hours!$A:$A,0))+J5*INDEX(Hours!F:F,MATCH(C5,Hours!$A:$A,0))+K5*INDEX(Hours!G:G,MATCH(C5,Hours!$A:$A,0))+O5*INDEX(Hours!K:K,MATCH(C5,Hours!$A:$A,0))) -> 0 | S5: =MAX(E5+F5,G5,H5,I5,J5,K5,L5,M5,N5,O5,P5,Q5) -> 0
A6: ='Bldgs & Rooms'!$A$2 -> Main Bldg. | B6: ='Bldgs & Rooms'!$B$2 -> 0 | C6: =Hours!$A$6 -> Switchboard Disconnects | D6: =MAX(E6+F6,G6,H6,I6,J6,K6,L6,M6,N6,O6,P6,Q6) -> 0 | E6: =IF('Components Yr 1'!E6=0,0,'Components Yr 1'!E6) -> 0 | F6: =IF('Components Yr 1'!F6=0,0,'Components Yr 1'!F6) -> 0 | G6: =IF('Components Yr 1'!G6=0,0,'Components Yr 1'!G6) -> 0 | H6: =IF('Components Yr 1'!H6=0,0,'Components Yr 1'!H6) -> 0 | I6: =IF('Components Yr 1'!I6=0,0,'Components Yr 1'!I6) -> 0 | J6: =IF('Components Yr 1'!J6=0,0,'Components Yr 1'!J6) -> 0 | R6: =IF(SUMPRODUCT((E6:Q6)*1)=0,0,E6*INDEX(Hours!M:M,MATCH(C6,Hours!$A:$A,0))+F6*INDEX(Hours!B:B,MATCH(C6,Hours!$A:$A,0))+G6*INDEX(Hours!C:C,MATCH(C6,Hours!$A:$A,0))+H6*INDEX(Hours!D:D,MATCH(C6,Hours!$A:$A,0))+I6*INDEX(Hours!E:E,MATCH(C6,Hours!$A:$A,0))+J6*INDEX(Hours!F:F,MATCH(C6,Hours!$A:$A,0))) -> 0 | S6: =MAX(E6+F6,G6,H6,I6,J6,K6,L6,M6,N6,O6,P6,Q6) -> 0
A7: ='Bldgs & Rooms'!$A$2 -> Main Bldg. | B7: ='Bldgs & Rooms'!$B$2 -> 0 | C7: =Hours!$A$7 -> Switchboard Molded Case Breakers | D7: =MAX(E7+F7,G7,H7,I7,J7,K7,L7,M7,N7,O7,P7,Q7) -> 0 | E7: =IF('Components Yr 1'!E7=0,0,'Components Yr 1'!E7) -> 0 | F7: =IF('Components Yr 1'!F7=0,0,'Components Yr 1'!F7) -> 0 | G7: =IF('Components Yr 1'!G7=0,0,'Components Yr 1'!G7) -> 0 | H7: =IF('Components Yr 1'!H7=0,0,'Components Yr 1'!H7) -> 0 | I7: =IF('Components Yr 1'!I7=0,0,'Components Yr 1'!I7) -> 0 | J7: =IF('Components Yr 1'!J7=0,0,'Components Yr 1'!J7) -> 0 | K7: =IF('Components Yr 1'!K7=0,0,'Components Yr 1'!K7) -> 0 | R7: =IF(SUMPRODUCT((E7:Q7)*1)=0,0,E7*INDEX(Hours!M:M,MATCH(C7,Hours!$A:$A,0))+F7*INDEX(Hours!B:B,MATCH(C7,Hours!$A:$A,0))+G7*INDEX(Hours!C:C,MATCH(C7,Hours!$A:$A,0))+H7*INDEX(Hours!D:D,MATCH(C7,Hours!$A:$A,0))+I7*INDEX(Hours!E:E,MATCH(C7,Hours!$A:$A,0))+J7*INDEX(Hours!F:F,MATCH(C7,Hours!$A:$A,0))+K7*INDEX(Hours!G:G,MATCH(C7,Hours!$A:$A,0))) -> 0 | S7: =MAX(E7+F7,G7,H7,I7,J7,K7,L7,M7,N7,O7,P7,Q7) -> 0
A8: ='Bldgs & Rooms'!$A$2 -> Main Bldg. | B8: ='Bldgs & Rooms'!$B$2 -> 0 | C8: =Hours!$A$8 -> Panelboard-Single Cover > 400A (Distribution Panel) | D8: =MAX(E8+F8,G8,H8,I8,J8,K8,L8,M8,N8,O8,P8,Q8) -> 0 | E8: =IF('Components Yr 1'!E8=0,0,'Components Yr 1'!E8) -> 0 | F8: =IF('Components Yr 1'!F8=0,0,'Components Yr 1'!F8) -> 0 | G8: =IF('Components Yr 1'!G8=0,0,'Components Yr 1'!G8) -> 0 | H8: =IF('Components Yr 1'!H8=0,0,'Components Yr 1'!H8) -> 0 | I8: =IF('Components Yr 1'!I8=0,0,'Components Yr 1'!I8) -> 0 | J8: =IF('Components Yr 1'!J8=0,0,'Components Yr 1'!J8) -> 0 | K8: =IF('Components Yr 1'!K8=0,0,'Components Yr 1'!K8) -> 0 | O8: =IF('Components Yr 1'!O8=0,0,'Components Yr 1'!O8) -> 0 | R8: =IF(SUMPRODUCT((E8:Q8)*1)=0,0,E8*INDEX(Hours!M:M,MATCH(C8,Hours!$A:$A,0))+F8*INDEX(Hours!B:B,MATCH(C8,Hours!$A:$A,0))+G8*INDEX(Hours!C:C,MATCH(C8,Hours!$A:$A,0))+H8*INDEX(Hours!D:D,MATCH(C8,Hours!$A:$A,0))+I8*INDEX(Hours!E:E,MATCH(C8,Hours!$A:$A,0))+J8*INDEX(Hours!F:F,MATCH(C8,Hours!$A:$A,0))+K8*INDEX(Hours!G:G,MATCH(C8,Hours!$A:$A,0))+O8*INDEX(Hours!K:K,MATCH(C8,Hours!$A:$A,0))) -> 0 | S8: =MAX(E8+F8,G8,H8,I8,J8,K8,L8,M8,N8,O8,P8,Q8) -> 0
A9: ='Bldgs & Rooms'!$A$2 -> Main Bldg. | B9: ='Bldgs & Rooms'!$B$2 -> 0 | C9: =Hours!$A$9 -> Panelboard-Single Cover < 400A (Branch Ckt Panel) | D9: =MAX(E9+F9,G9,H9,I9,J9,K9,L9,M9,N9,O9,P9,Q9) -> 0 | E9: =IF('Components Yr 1'!E9=0,0,'Components Yr 1'!E9) -> 0 | F9: =IF('Components Yr 1'!F9=0,0,'Components Yr 1'!F9) -> 0 | G9: =IF('Components Yr 1'!G9=0,0,'Components Yr 1'!G9) -> 0 | H9: =IF('Components Yr 1'!H9=0,0,'Components Yr 1'!H9) -> 0 | I9: =IF('Components Yr 1'!I9=0,0,'Components Yr 1'!I9) -> 0 | J9: =IF('Components Yr 1'!J9=0,0,'Components Yr 1'!J9) -> 0 | O9: =IF('Components Yr 1'!O9=0,0,'Components Yr 1'!O9) -> 0 | R9: =IF(SUMPRODUCT((E9:Q9)*1)=0,0,E9*INDEX(Hours!M:M,MATCH(C9,Hours!$A:$A,0))+F9*INDEX(Hours!B:B,MATCH(C9,Hours!$A:$A,0))+G9*INDEX(Hours!C:C,MATCH(C9,Hours!$A:$A,0))+H9*INDEX(Hours!D:D,MATCH(C9,Hours!$A:$A,0))+I9*INDEX(Hours!E:E,MATCH(C9,Hours!$A:$A,0))+J9*INDEX(Hours!F:F,MATCH(C9,Hours!$A:$A,0))+O9*INDEX(Hours!K:K,MATCH(C9,Hours!$A:$A,0))) -> 0 | S9: =MAX(E9+F9,G9,H9,I9,J9,K9,L9,M9,N9,O9,P9,Q9) -> 0
A10: ='Bldgs & Rooms'!$A$2 -> Main Bldg. | B10: ='Bldgs & Rooms'!$B$2 -> 0 | C10: =Hours!$A$10 -> Motor Control Center (MCC-Per Vertical Section) | D10: =MAX(E10+F10,G10,H10,I10,J10,K10,L10,M10,N10,O10,P10,Q10) -> 0 | E10: =IF('Components Yr 1'!E10=0,0,'Components Yr 1'!E10) -> 0 | F10: =IF('Components Yr 1'!F10=0,0,'Components Yr 1'!F10) -> 0 | G10: =IF('Components Yr 1'!G10=0,0,'Components Yr 1'!G10) -> 0 | H10: =IF('Components Yr 1'!H10=0,0,'Components Yr 1'!H10) -> 0 | I10: =IF('Components Yr 1'!I10=0,0,'Components Yr 1'!I10) -> 0 | J10: =IF('Components Yr 1'!J10=0,0,'Components Yr 1'!J10) -> 0 | O10: =IF('Components Yr 1'!O10=0,0,'Components Yr 1'!O10) -> 0 | R10: =IF(SUMPRODUCT((E10:Q10)*1)=0,0,E10*INDEX(Hours!M:M,MATCH(C10,Hours!$A:$A,0))+F10*INDEX(Hours!B:B,MATCH(C10,Hours!$A:$A,0))+G10*INDEX(Hours!C:C,MATCH(C10,Hours!$A:$A,0))+H10*INDEX(Hours!D:D,MATCH(C10,Hours!$A:$A,0))+I10*INDEX(Hours!E:E,MATCH(C10,Hours!$A:$A,0))+J10*INDEX(Hours!F:F,MATCH(C10,Hours!$A:$A,0))+O10*INDEX(Hours!K:K,MATCH(C10,Hours!$A:$A,0))) -> 0 | S10: =MAX(E10+F10,G10,H10,I10,J10,K10,L10,M10,N10,O10,P10,Q10) -> 0
A11: ='Bldgs & Rooms'!$A$2 -> Main Bldg. | B11: ='Bldgs & Rooms'!$B$2 -> 0 | C11: =Hours!$A$11 -> MCC: Combination Motor Starters | D11: =MAX(E11+F11,G11,H11,I11,J11,K11,L11,M11,N11,O11,P11,Q11) -> 0 | E11: =IF('Components Yr 1'!E11=0,0,'Components Yr 1'!E11) -> 0 | F11: =IF('Components Yr 1'!F11=0,0,'Components Yr 1'!F11) -> 0 | G11: =IF('Components Yr 1'!G11=0,0,'Components Yr 1'!G11) -> 0 | H11: =IF('Components Yr 1'!H11=0,0,'Components Yr 1'!H11) -> 0 | I11: =IF('Components Yr 1'!I11=0,0,'Components Yr 1'!I11) -> 0 | J11: =IF('Components Yr 1'!J11=0,0,'Components Yr 1'!J11) -> 0 | K11: =IF('Components Yr 1'!K11=0,0,'Components Yr 1'!K11) -> 0 | O11: =IF('Components Yr 1'!O11=0,0,'Components Yr 1'!O11) -> 0 | R11: =IF(SUMPRODUCT((E11:Q11)*1)=0,0,E11*INDEX(Hours!M:M,MATCH(C11,Hours!$A:$A,0))+F11*INDEX(Hours!B:B,MATCH(C11,Hours!$A:$A,0))+G11*INDEX(Hours!C:C,MATCH(C11,Hours!$A:$A,0))+H11*INDEX(Hours!D:D,MATCH(C11,Hours!$A:$A,0))+I11*INDEX(Hours!E:E,MATCH(C11,Hours!$A:$A,0))+J11*INDEX(Hours!F:F,MATCH(C11,Hours!$A:$A,0))+K11*INDEX(Hours!G:G,MATCH(C11,Hours!$A:$A,0))+O11*INDEX(Hours!K:K,MATCH(C11,Hours!$A:$A,0))) -> 0 | S11: =MAX(E11+F11,G11,H11,I11,J11,K11,L11,M11,N11,O11,P11,Q11) -> 0
A12: ='Bldgs & Rooms'!$A$2 -> Main Bldg. | B12: ='Bldgs & Rooms'!$B$2 -> 0 | C12: =Hours!$A$12 -> MCC: Molded Case Breaker | D12: =MAX(E12+F12,G12,H12,I12,J12,K12,L12,M12,N12,O12,P12,Q12) -> 0 | E12: =IF('Components Yr 1'!E12=0,0,'Components Yr 1'!E12) -> 0 | F12: =IF('Components Yr 1'!F12=0,0,'Components Yr 1'!F12) -> 0 | G12: =IF('Components Yr 1'!G12=0,0,'Components Yr 1'!G12) -> 0 | H12: =IF('Components Yr 1'!H12=0,0,'Components Yr 1'!H12) -> 0 | I12: =IF('Components Yr 1'!I12=0,0,'Components Yr 1'!I12) -> 0 | J12: =IF('Components Yr 1'!J12=0,0,'Components Yr 1'!J12) -> 0 | K12: =IF('Components Yr 1'!K12=0,0,'Components Yr 1'!K12) -> 0 | R12: =IF(SUMPRODUCT((E12:Q12)*1)=0,0,E12*INDEX(Hours!M:M,MATCH(C12,Hours!$A:$A,0))+F12*INDEX(Hours!B:B,MATCH(C12,Hours!$A:$A,0))+G12*INDEX(Hours!C:C,MATCH(C12,Hours!$A:$A,0))+H12*INDEX(Hours!D:D,MATCH(C12,Hours!$A:$A,0))+I12*INDEX(Hours!E:E,MATCH(C12,Hours!$A:$A,0))+J12*INDEX(Hours!F:F,MATCH(C12,Hours!$A:$A,0))+K12*INDEX(Hours!G:G,MATCH(C12,Hours!$A:$A,0))) -> 0 | S12: =MAX(E12+F12,G12,H12,I12,J12,K12,L12,M12,N12,O12,P12,Q12) -> 0
A13: ='Bldgs & Rooms'!$A$2 -> Main Bldg. | B13: ='Bldgs & Rooms'!$B$2 -> 0 | C13: =Hours!$A$13 -> MCC: Individual Disconnect Switch | D13: =MAX(E13+F13,G13,H13,I13,J13,K13,L13,M13,N13,O13,P13,Q13) -> 0 | E13: =IF('Components Yr 1'!E13=0,0,'Components Yr 1'!E13) -> 0 | F13: =IF('Components Yr 1'!F13=0,0,'Components Yr 1'!F13) -> 0 | G13: =IF('Components Yr 1'!G13=0,0,'Components Yr 1'!G13) -> 0 | H13: =IF('Components Yr 1'!H13=0,0,'Components Yr 1'!H13) -> 0 | I13: =IF('Components Yr 1'!I13=0,0,'Components Yr 1'!I13) -> 0 | J13: =IF('Components Yr 1'!J13=0,0,'Components Yr 1'!J13) -> 0 | R13: =IF(SUMPRODUCT((E13:Q13)*1)=0,0,E13*INDEX(Hours!M:M,MATCH(C13,Hours!$A:$A,0))+F13*INDEX(Hours!B:B,MATCH(C13,Hours!$A:$A,0))+G13*INDEX(Hours!C:C,MATCH(C13,Hours!$A:$A,0))+H13*INDEX(Hours!D:D,MATCH(C13,Hours!$A:$A,0))+I13*INDEX(Hours!E:E,MATCH(C13,Hours!$A:$A,0))+J13*INDEX(Hours!F:F,MATCH(C13,Hours!$A:$A,0))) -> 0 | S13: =MAX(E13+F13,G13,H13,I13,J13,K13,L13,M13,N13,O13,P13,Q13) -> 0
A14: ='Bldgs & Rooms'!$A$2 -> Main Bldg. | B14: ='Bldgs & Rooms'!$B$2 -> 0 | C14: =Hours!$A$14 -> Motor Control Panel (MCP) | D14: =MAX(E14+F14,G14,H14,I14,J14,K14,L14,M14,N14,O14,P14,Q14) -> 0 | E14: =IF('Components Yr 1'!E14=0,0,'Components Yr 1'!E14) -> 0 | F14: =IF('Components Yr 1'!F14=0,0,'Components Yr 1'!F14) -> 0 | G14: =IF('Components Yr 1'!G14=0,0,'Components Yr 1'!G14) -> 0 | H14: =IF('Components Yr 1'!H14=0,0,'Components Yr 1'!H14) -> 0 | I14: =IF('Components Yr 1'!I14=0,0,'Components Yr 1'!I14) -> 0 | J14: =IF('Components Yr 1'!J14=0,0,'Components Yr 1'!J14) -> 0 | O14: =IF('Components Yr 1'!O14=0,0,'Components Yr 1'!O14) -> 0 | R14: =IF(SUMPRODUCT((E14:Q14)*1)=0,0,E14*INDEX(Hours!M:M,MATCH(C14,Hours!$A:$A,0))+F14*INDEX(Hours!B:B,MATCH(C14,Hours!$A:$A,0))+G14*INDEX(Hours!C:C,MATCH(C14,Hours!$A:$A,0))+H14*INDEX(Hours!D:D,MATCH(C14,Hours!$A:$A,0))+I14*INDEX(Hours!E:E,MATCH(C14,Hours!$A:$A,0))+J14*INDEX(Hours!F:F,MATCH(C14,Hours!$A:$A,0))+O14*INDEX(Hours!K:K,MATCH(C14,Hours!$A:$A,0))) -> 0 | S14: =MAX(E14+F14,G14,H14,I14,J14,K14,L14,M14,N14,O14,P14,Q14) -> 0
A15: ='Bldgs & Rooms'!$A$2 -> Main Bldg. | B15: ='Bldgs & Rooms'!$B$2 -> 0 | C15: =Hours!$A$15 -> VFD Motor Control Panel (VFD-MCP) | D15: =MAX(E15+F15,G15,H15,I15,J15,K15,L15,M15,N15,O15,P15,Q15) -> 0 | E15: =IF('Components Yr 1'!E15=0,0,'Components Yr 1'!E15) -> 0 | F15: =IF('Components Yr 1'!F15=0,0,'Components Yr 1'!F15) -> 0 | G15: =IF('Components Yr 1'!G15=0,0,'Components Yr 1'!G15) -> 0 | H15: =IF('Components Yr 1'!H15=0,0,'Components Yr 1'!H15) -> 0 | I15: =IF('Components Yr 1'!I15=0,0,'Components Yr 1'!I15) -> 0 | J15: =IF('Components Yr 1'!J15=0,0,'Components Yr 1'!J15) -> 0 | O15: =IF('Components Yr 1'!O15=0,0,'Components Yr 1'!O15) -> 0 | R15: =IF(SUMPRODUCT((E15:Q15)*1)=0,0,E15*INDEX(Hours!M:M,MATCH(C15,Hours!$A:$A,0))+F15*INDEX(Hours!B:B,MATCH(C15,Hours!$A:$A,0))+G15*INDEX(Hours!C:C,MATCH(C15,Hours!$A:$A,0))+H15*INDEX(Hours!D:D,MATCH(C15,Hours!$A:$A,0))+I15*INDEX(Hours!E:E,MATCH(C15,Hours!$A:$A,0))+J15*INDEX(Hours!F:F,MATCH(C15,Hours!$A:$A,0))+O15*INDEX(Hours!K:K,MATCH(C15,Hours!$A:$A,0))) -> 0 | S15: =MAX(E15+F15,G15,H15,I15,J15,K15,L15,M15,N15,O15,P15,Q15) -> 0
A16: ='Bldgs & Rooms'!$A$2 -> Main Bldg. | B16: ='Bldgs & Rooms'!$B$2 -> 0 | C16: =Hours!$A$16 -> Individual Disconnect Switch > 100A | D16: =MAX(E16+F16,G16,H16,I16,J16,K16,L16,M16,N16,O16,P16,Q16) -> 0 | E16: =IF('Components Yr 1'!E16=0,0,'Components Yr 1'!E16) -> 0 | F16: =IF('Components Yr 1'!F16=0,0,'Components Yr 1'!F16) -> 0 | G16: =IF('Components Yr 1'!G16=0,0,'Components Yr 1'!G16) -> 0 | H16: =IF('Components Yr 1'!H16=0,0,'Components Yr 1'!H16) -> 0 | I16: =IF('Components Yr 1'!I16=0,0,'Components Yr 1'!I16) -> 0 | J16: =IF('Components Yr 1'!J16=0,0,'Components Yr 1'!J16) -> 0 | K16: =IF('Components Yr 1'!K16=0,0,'Components Yr 1'!K16) -> 0 | R16: =IF(SUMPRODUCT((E16:Q16)*1)=0,0,E16*INDEX(Hours!M:M,MATCH(C16,Hours!$A:$A,0))+F16*INDEX(Hours!B:B,MATCH(C16,Hours!$A:$A,0))+G16*INDEX(Hours!C:C,MATCH(C16,Hours!$A:$A,0))+H16*INDEX(Hours!D:D,MATCH(C16,Hours!$A:$A,0))+I16*INDEX(Hours!E:E,MATCH(C16,Hours!$A:$A,0))+J16*INDEX(Hours!F:F,MATCH(C16,Hours!$A:$A,0))+K16*INDEX(Hours!G:G,MATCH(C16,Hours!$A:$A,0))) -> 0 | S16: =MAX(E16+F16,G16,H16,I16,J16,K16,L16,M16,N16,O16,P16,Q16) -> 0
A17: ='Bldgs & Rooms'!$A$2 -> Main Bldg. | B17: ='Bldgs & Rooms'!$B$2 -> 0 | C17: =Hours!$A$17 -> Individual Molded Case Breaker > 100A | D17: =MAX(E17+F17,G17,H17,I17,J17,K17,L17,M17,N17,O17,P17,Q17) -> 0 | E17: =IF('Components Yr 1'!E17=0,0,'Components Yr 1'!E17) -> 0 | F17: =IF('Components Yr 1'!F17=0,0,'Components Yr 1'!F17) -> 0 | G17: =IF('Components Yr 1'!G17=0,0,'Components Yr 1'!G17) -> 0 | H17: =IF('Components Yr 1'!H17=0,0,'Components Yr 1'!H17) -> 0 | I17: =IF('Components Yr 1'!I17=0,0,'Components Yr 1'!I17) -> 0 | J17: =IF('Components Yr 1'!J17=0,0,'Components Yr 1'!J17) -> 0 | K17: =IF('Components Yr 1'!K17=0,0,'Components Yr 1'!K17) -> 0 | R17: =IF(SUMPRODUCT((E17:Q17)*1)=0,0,E17*INDEX(Hours!M:M,MATCH(C17,Hours!$A:$A,0))+F17*INDEX(Hours!B:B,MATCH(C17,Hours!$A:$A,0))+G17*INDEX(Hours!C:C,MATCH(C17,Hours!$A:$A,0))+H17*INDEX(Hours!D:D,MATCH(C17,Hours!$A:$A,0))+I17*INDEX(Hours!E:E,MATCH(C17,Hours!$A:$A,0))+J17*INDEX(Hours!F:F,MATCH(C17,Hours!$A:$A,0))+K17*INDEX(Hours!G:G,MATCH(C17,Hours!$A:$A,0))) -> 0 | S17: =MAX(E17+F17,G17,H17,I17,J17,K17,L17,M17,N17,O17,P17,Q17) -> 0
A18: ='Bldgs & Rooms'!$A$2 -> Main Bldg. | B18: ='Bldgs & Rooms'!$B$2 -> 0 | C18: =Hours!$A$18 -> Individual Combination Motor Starter > 100A | D18: =MAX(E18+F18,G18,H18,I18,J18,K18,L18,M18,N18,O18,P18,Q18) -> 0 | E18: =IF('Components Yr 1'!E18=0,0,'Components Yr 1'!E18) -> 0 | F18: =IF('Components Yr 1'!F18=0,0,'Components Yr 1'!F18) -> 0 | G18: =IF('Components Yr 1'!G18=0,0,'Components Yr 1'!G18) -> 0 | H18: =IF('Components Yr 1'!H18=0,0,'Components Yr 1'!H18) -> 0 | I18: =IF('Components Yr 1'!I18=0,0,'Components Yr 1'!I18) -> 0 | J18: =IF('Components Yr 1'!J18=0,0,'Components Yr 1'!J18) -> 0 | K18: =IF('Components Yr 1'!K18=0,0,'Components Yr 1'!K18) -> 0 | R18: =IF(SUMPRODUCT((E18:Q18)*1)=0,0,E18*INDEX(Hours!M:M,MATCH(C18,Hours!$A:$A,0))+F18*INDEX(Hours!B:B,MATCH(C18,Hours!$A:$A,0))+G18*INDEX(Hours!C:C,MATCH(C18,Hours!$A:$A,0))+H18*INDEX(Hours!D:D,MATCH(C18,Hours!$A:$A,0))+I18*INDEX(Hours!E:E,MATCH(C18,Hours!$A:$A,0))+J18*INDEX(Hours!F:F,MATCH(C18,Hours!$A:$A,0))+K18*INDEX(Hours!G:G,MATCH(C18,Hours!$A:$A,0))) -> 0 | S18: =MAX(E18+F18,G18,H18,I18,J18,K18,L18,M18,N18,O18,P18,Q18) -> 0
A19: ='Bldgs & Rooms'!$A$2 -> Main Bldg. | B19: ='Bldgs & Rooms'!$B$2 -> 0 | C19: =Hours!$A$19 -> Oil Filled Transformer - 5kV-15kV Primary - Any Size (Pad Mounted) | D19: =MAX(E19+F19,G19,H19,I19,J19,K19,L19,M19,N19,O19,P19,Q19) -> 0 | E19: =IF('Components Yr 1'!E19=0,0,'Components Yr 1'!E19) -> 0 | F19: =IF('Components Yr 1'!F19=0,0,'Components Yr 1'!F19) -> 0 | G19: =IF('Components Yr 1'!G19=0,0,'Components Yr 1'!G19) -> 0 | H19: =IF('Components Yr 1'!H19=0,0,'Components Yr 1'!H19) -> 0 | I19: =IF('Components Yr 1'!I19=0,0,'Components Yr 1'!I19) -> 0 | J19: =IF('Components Yr 1'!J19=0,0,'Components Yr 1'!J19) -> 0 | M19: =IF('Components Yr 1'!M19=0,0,'Components Yr 1'!M19) -> 0 | N19: =IF('Components Yr 1'!N19=0,0,'Components Yr 1'!N19) -> 0 | P19: =IF('Components Yr 1'!P19=0,0,'Components Yr 1'!P19) -> 0 | R19: =IF(SUMPRODUCT((E19:Q19)*1)=0,0,E19*INDEX(Hours!M:M,MATCH(C19,Hours!$A:$A,0))+F19*INDEX(Hours!B:B,MATCH(C19,Hours!$A:$A,0))+G19*INDEX(Hours!C:C,MATCH(C19,Hours!$A:$A,0))+H19*INDEX(Hours!D:D,MATCH(C19,Hours!$A:$A,0))+I19*INDEX(Hours!E:E,MATCH(C19,Hours!$A:$A,0))+J19*INDEX(Hours!F:F,MATCH(C19,Hours!$A:$A,0))+M19*INDEX(Hours!I:I,MATCH(C19,Hours!$A:$A,0))+N19*INDEX(Hours!J:J,MATCH(C19,Hours!$A:$A,0))+P19*INDEX(Hours!L:L,MATCH(C19,Hours!$A:$A,0))) -> 0 | S19: =MAX(E19+F19,G19,H19,I19,J19,K19,L19,M19,N19,O19,P19,Q19) -> 0
A20: ='Bldgs & Rooms'!$A$2 -> Main Bldg. | B20: ='Bldgs & Rooms'!$B$2 -> 0 | C20: =Hours!$A$20 -> Oil Filled Transformer - > 15kV Primary (Substation Class) | D20: =MAX(E20+F20,G20,H20,I20,J20,K20,L20,M20,N20,O20,P20,Q20) -> 0 | E20: =IF('Components Yr 1'!E20=0,0,'Components Yr 1'!E20) -> 0 | F20: =IF('Components Yr 1'!F20=0,0,'Components Yr 1'!F20) -> 0 | G20: =IF('Components Yr 1'!G20=0,0,'Components Yr 1'!G20) -> 0 | H20: =IF('Components Yr 1'!H20=0,0,'Components Yr 1'!H20) -> 0 | I20: =IF('Components Yr 1'!I20=0,0,'Components Yr 1'!I20) -> 0 | J20: =IF('Components Yr 1'!J20=0,0,'Components Yr 1'!J20) -> 0 | M20: =IF('Components Yr 1'!M20=0,0,'Components Yr 1'!M20) -> 0 | N20: =IF('Components Yr 1'!N20=0,0,'Components Yr 1'!N20) -> 0 | P20: =IF('Components Yr 1'!P20=0,0,'Components Yr 1'!P20) -> 0 | R20: =IF(SUMPRODUCT((E20:Q20)*1)=0,0,E20*INDEX(Hours!M:M,MATCH(C20,Hours!$A:$A,0))+F20*INDEX(Hours!B:B,MATCH(C20,Hours!$A:$A,0))+G20*INDEX(Hours!C:C,MATCH(C20,Hours!$A:$A,0))+H20*INDEX(Hours!D:D,MATCH(C20,Hours!$A:$A,0))+I20*INDEX(Hours!E:E,MATCH(C20,Hours!$A:$A,0))+J20*INDEX(Hours!F:F,MATCH(C20,Hours!$A:$A,0))+M20*INDEX(Hours!I:I,MATCH(C20,Hours!$A:$A,0))+N20*INDEX(Hours!J:J,MATCH(C20,Hours!$A:$A,0))+P20*INDEX(Hours!L:L,MATCH(C20,Hours!$A:$A,0))) -> 0 | S20: =MAX(E20+F20,G20,H20,I20,J20,K20,L20,M20,N20,O20,P20,Q20) -> 0
A21: ='Bldgs & Rooms'!$A$2 -> Main Bldg. | B21: ='Bldgs & Rooms'!$B$2 -> 0 | C21: =Hours!$A$21 -> Dry Type Transformer - < 480V Primary - Any Size kVA | D21: =MAX(E21+F21,G21,H21,I21,J21,K21,L21,M21,N21,O21,P21,Q21) -> 0 | E21: =IF('Components Yr 1'!E21=0,0,'Components Yr 1'!E21) -> 0 | F21: =IF('Components Yr 1'!F21=0,0,'Components Yr 1'!F21) -> 0 | G21: =IF('Components Yr 1'!G21=0,0,'Components Yr 1'!G21) -> 0 | H21: =IF('Components Yr 1'!H21=0,0,'Components Yr 1'!H21) -> 0 | I21: =IF('Components Yr 1'!I21=0,0,'Components Yr 1'!I21) -> 0 | J21: =IF('Components Yr 1'!J21=0,0,'Components Yr 1'!J21) -> 0 | M21: =IF('Components Yr 1'!M21=0,0,'Components Yr 1'!M21) -> 0 | N21: =IF('Components Yr 1'!N21=0,0,'Components Yr 1'!N21) -> 0 | R21: =IF(SUMPRODUCT((E21:Q21)*1)=0,0,E21*INDEX(Hours!M:M,MATCH(C21,Hours!$A:$A,0))+F21*INDEX(Hours!B:B,MATCH(C21,Hours!$A:$A,0))+G21*INDEX(Hours!C:C,MATCH(C21,Hours!$A:$A,0))+H21*INDEX(Hours!D:D,MATCH(C21,Hours!$A:$A,0))+I21*INDEX(Hours!E:E,MATCH(C21,Hours!$A:$A,0))+J21*INDEX(Hours!F:F,MATCH(C21,Hours!$A:$A,0))+M21*INDEX(Hours!I:I,MATCH(C21,Hours!$A:$A,0))+N21*INDEX(Hours!J:J,MATCH(C21,Hours!$A:$A,0))) -> 0 | S21: =MAX(E21+F21,G21,H21,I21,J21,K21,L21,M21,N21,O21,P21,Q21) -> 0
A22: ='Bldgs & Rooms'!$A$2 -> Main Bldg. | B22: ='Bldgs & Rooms'!$B$2 -> 0 | C22: =Hours!$A$22 -> Power Factor Correction Capacitors | D22: =MAX(E22+F22,G22,H22,I22,J22,K22,L22,M22,N22,O22,P22,Q22) -> 0 | E22: =IF('Components Yr 1'!E22=0,0,'Components Yr 1'!E22) -> 0 | F22: =IF('Components Yr 1'!F22=0,0,'Components Yr 1'!F22) -> 0 | G22: =IF('Components Yr 1'!G22=0,0,'Components Yr 1'!G22) -> 0 | H22: =IF('Components Yr 1'!H22=0,0,'Components Yr 1'!H22) -> 0 | I22: =IF('Components Yr 1'!I22=0,0,'Components Yr 1'!I22) -> 0 | J22: =IF('Components Yr 1'!J22=0,0,'Components Yr 1'!J22) -> 0 | R22: =IF(SUMPRODUCT((E22:Q22)*1)=0,0,E22*INDEX(Hours!M:M,MATCH(C22,Hours!$A:$A,0))+F22*INDEX(Hours!B:B,MATCH(C22,Hours!$A:$A,0))+G22*INDEX(Hours!C:C,MATCH(C22,Hours!$A:$A,0))+H22*INDEX(Hours!D:D,MATCH(C22,Hours!$A:$A,0))+I22*INDEX(Hours!E:E,MATCH(C22,Hours!$A:$A,0))+J22*INDEX(Hours!F:F,MATCH(C22,Hours!$A:$A,0))) -> 0 | S22: =MAX(E22+F22,G22,H22,I22,J22,K22,L22,M22,N22,O22,P22,Q22) -> 0
A23: ='Bldgs & Rooms'!$A$2 -> Main Bldg. | B23: ='Bldgs & Rooms'!$B$2 -> 0 | C23: =Hours!$A$23 -> Lighting Contactor > 100A | D23: =MAX(E23+F23,G23,H23,I23,J23,K23,L23,M23,N23,O23,P23,Q23) -> 0 | E23: =IF('Components Yr 1'!E23=0,0,'Components Yr 1'!E23) -> 0 | F23: =IF('Components Yr 1'!F23=0,0,'Components Yr 1'!F23) -> 0 | G23: =IF('Components Yr 1'!G23=0,0,'Components Yr 1'!G23) -> 0 | H23: =IF('Components Yr 1'!H23=0,0,'Components Yr 1'!H23) -> 0 | I23: =IF('Components Yr 1'!I23=0,0,'Components Yr 1'!I23) -> 0 | J23: =IF('Components Yr 1'!J23=0,0,'Components Yr 1'!J23) -> 0 | R23: =IF(SUMPRODUCT((E23:Q23)*1)=0,0,E23*INDEX(Hours!M:M,MATCH(C23,Hours!$A:$A,0))+F23*INDEX(Hours!B:B,MATCH(C23,Hours!$A:$A,0))+G23*INDEX(Hours!C:C,MATCH(C23,Hours!$A:$A,0))+H23*INDEX(Hours!D:D,MATCH(C23,Hours!$A:$A,0))+I23*INDEX(Hours!E:E,MATCH(C23,Hours!$A:$A,0))+J23*INDEX(Hours!F:F,MATCH(C23,Hours!$A:$A,0))) -> 0 | S23: =MAX(E23+F23,G23,H23,I23,J23,K23,L23,M23,N23,O23,P23,Q23) -> 0
A24: ='Bldgs & Rooms'!$A$2 -> Main Bldg. | B24: ='Bldgs & Rooms'!$B$2 -> 0 | C24: =Hours!$A$24 -> Power Distribution Unit (PDU) | D24: =MAX(E24+F24,G24,H24,I24,J24,K24,L24,M24,N24,O24,P24,Q24) -> 0 | E24: =IF('Components Yr 1'!E24=0,0,'Components Yr 1'!E24) -> 0 | F24: =IF('Components Yr 1'!F24=0,0,'Components Yr 1'!F24) -> 0 | G24: =IF('Components Yr 1'!G24=0,0,'Components Yr 1'!G24) -> 0 | H24: =IF('Components Yr 1'!H24=0,0,'Components Yr 1'!H24) -> 0 | I24: =IF('Components Yr 1'!I24=0,0,'Components Yr 1'!I24) -> 0 | J24: =IF('Components Yr 1'!J24=0,0,'Components Yr 1'!J24) -> 0 | R24: =IF(SUMPRODUCT((E24:Q24)*1)=0,0,E24*INDEX(Hours!M:M,MATCH(C24,Hours!$A:$A,0))+F24*INDEX(Hours!B:B,MATCH(C24,Hours!$A:$A,0))+G24*INDEX(Hours!C:C,MATCH(C24,Hours!$A:$A,0))+H24*INDEX(Hours!D:D,MATCH(C24,Hours!$A:$A,0))+I24*INDEX(Hours!E:E,MATCH(C24,Hours!$A:$A,0))+J24*INDEX(Hours!F:F,MATCH(C24,Hours!$A:$A,0))) -> 0 | S24: =MAX(E24+F24,G24,H24,I24,J24,K24,L24,M24,N24,O24,P24,Q24) -> 0
A25: ='Bldgs & Rooms'!$A$2 -> Main Bldg. | B25: ='Bldgs & Rooms'!$B$2 -> 0 | C25: =Hours!$A$25 -> Wire Trough, Gutter, or Large Junction Boxes | D25: =MAX(E25+F25,G25,H25,I25,J25,K25,L25,M25,N25,O25,P25,Q25) -> 0 | E25: =IF('Components Yr 1'!E25=0,0,'Components Yr 1'!E25) -> 0 | F25: =IF('Components Yr 1'!F25=0,0,'Components Yr 1'!F25) -> 0 | G25: =IF('Components Yr 1'!G25=0,0,'Components Yr 1'!G25) -> 0 | H25: =IF('Components Yr 1'!H25=0,0,'Components Yr 1'!H25) -> 0 | I25: =IF('Components Yr 1'!I25=0,0,'Components Yr 1'!I25) -> 0 | J25: =IF('Components Yr 1'!J25=0,0,'Components Yr 1'!J25) -> 0 | R25: =IF(SUMPRODUCT((E25:Q25)*1)=0,0,E25*INDEX(Hours!M:M,MATCH(C25,Hours!$A:$A,0))+F25*INDEX(Hours!B:B,MATCH(C25,Hours!$A:$A,0))+G25*INDEX(Hours!C:C,MATCH(C25,Hours!$A:$A,0))+H25*INDEX(Hours!D:D,MATCH(C25,Hours!$A:$A,0))+I25*INDEX(Hours!E:E,MATCH(C25,Hours!$A:$A,0))+J25*INDEX(Hours!F:F,MATCH(C25,Hours!$A:$A,0))) -> 0 | S25: =MAX(E25+F25,G25,H25,I25,J25,K25,L25,M25,N25,O25,P25,Q25) -> 0
A26: ='Bldgs & Rooms'!$A$2 -> Main Bldg. | B26: ='Bldgs & Rooms'!$B$2 -> 0 | C26: =Hours!$A$26 -> Bus Duct - Vertical or Horizontal (Per 10' section) | D26: =MAX(E26+F26,G26,H26,I26,J26,K26,L26,M26,N26,O26,P26,Q26) -> 0 | E26: =IF('Components Yr 1'!E26=0,0,'Components Yr 1'!E26) -> 0 | F26: =IF('Components Yr 1'!F26=0,0,'Components Yr 1'!F26) -> 0 | G26: =IF('Components Yr 1'!G26=0,0,'Components Yr 1'!G26) -> 0 | H26: =IF('Components Yr 1'!H26=0,0,'Components Yr 1'!H26) -> 0 | I26: =IF('Components Yr 1'!I26=0,0,'Components Yr 1'!I26) -> 0 | J26: =IF('Components Yr 1'!J26=0,0,'Components Yr 1'!J26) -> 0 | R26: =IF(SUMPRODUCT((E26:Q26)*1)=0,0,E26*INDEX(Hours!M:M,MATCH(C26,Hours!$A:$A,0))+F26*INDEX(Hours!B:B,MATCH(C26,Hours!$A:$A,0))+G26*INDEX(Hours!C:C,MATCH(C26,Hours!$A:$A,0))+H26*INDEX(Hours!D:D,MATCH(C26,Hours!$A:$A,0))+I26*INDEX(Hours!E:E,MATCH(C26,Hours!$A:$A,0))+J26*INDEX(Hours!F:F,MATCH(C26,Hours!$A:$A,0))) -> 0 | S26: =MAX(E26+F26,G26,H26,I26,J26,K26,L26,M26,N26,O26,P26,Q26) -> 0
A27: ='Bldgs & Rooms'!$A$2 -> Main Bldg. | B27: ='Bldgs & Rooms'!$B$2 -> 0 | C27: =Hours!$A$27 -> Automatic Transfer Switch (ATS) > 100A | D27: =MAX(E27+F27,G27,H27,I27,J27,K27,L27,M27,N27,O27,P27,Q27) -> 0 | E27: =IF('Components Yr 1'!E27=0,0,'Components Yr 1'!E27) -> 0 | F27: =IF('Components Yr 1'!F27=0,0,'Components Yr 1'!F27) -> 0 | G27: =IF('Components Yr 1'!G27=0,0,'Components Yr 1'!G27) -> 0 | H27: =IF('Components Yr 1'!H27=0,0,'Components Yr 1'!H27) -> 0 | I27: =IF('Components Yr 1'!I27=0,0,'Components Yr 1'!I27) -> 0 | J27: =IF('Components Yr 1'!J27=0,0,'Components Yr 1'!J27) -> 0 | R27: =IF(SUMPRODUCT((E27:Q27)*1)=0,0,E27*INDEX(Hours!M:M,MATCH(C27,Hours!$A:$A,0))+F27*INDEX(Hours!B:B,MATCH(C27,Hours!$A:$A,0))+G27*INDEX(Hours!C:C,MATCH(C27,Hours!$A:$A,0))+H27*INDEX(Hours!D:D,MATCH(C27,Hours!$A:$A,0))+I27*INDEX(Hours!E:E,MATCH(C27,Hours!$A:$A,0))+J27*INDEX(Hours!F:F,MATCH(C27,Hours!$A:$A,0))) -> 0 | S27: =MAX(E27+F27,G27,H27,I27,J27,K27,L27,M27,N27,O27,P27,Q27) -> 0
A28: ='Bldgs & Rooms'!$A$2 -> Main Bldg. | B28: ='Bldgs & Rooms'!$B$2 -> 0 | C28: =Hours!$A$28 -> Manual Transfer Switch (MTS) > 100A | D28: =MAX(E28+F28,G28,H28,I28,J28,K28,L28,M28,N28,O28,P28,Q28) -> 0 | E28: =IF('Components Yr 1'!E28=0,0,'Components Yr 1'!E28) -> 0 | F28: =IF('Components Yr 1'!F28=0,0,'Components Yr 1'!F28) -> 0 | G28: =IF('Components Yr 1'!G28=0,0,'Components Yr 1'!G28) -> 0 | H28: =IF('Components Yr 1'!H28=0,0,'Components Yr 1'!H28) -> 0 | I28: =IF('Components Yr 1'!I28=0,0,'Components Yr 1'!I28) -> 0 | J28: =IF('Components Yr 1'!J28=0,0,'Components Yr 1'!J28) -> 0 | R28: =IF(SUMPRODUCT((E28:Q28)*1)=0,0,E28*INDEX(Hours!M:M,MATCH(C28,Hours!$A:$A,0))+F28*INDEX(Hours!B:B,MATCH(C28,Hours!$A:$A,0))+G28*INDEX(Hours!C:C,MATCH(C28,Hours!$A:$A,0))+H28*INDEX(Hours!D:D,MATCH(C28,Hours!$A:$A,0))+I28*INDEX(Hours!E:E,MATCH(C28,Hours!$A:$A,0))+J28*INDEX(Hours!F:F,MATCH(C28,Hours!$A:$A,0))) -> 0 | S28: =MAX(E28+F28,G28,H28,I28,J28,K28,L28,M28,N28,O28,P28,Q28) -> 0
